<robot name="sparky">

<resource type="stl_meshes" location="/home/gavin/ros/stacks/interaction_ros_pkgs/sparky_model/meshes
"/>



<link name="shoulders">

<inertial>
		<mass value="5"/>
		<inertia ixx="100" ixy="0" ixz="0" iyy="100" iyz="0" izz="100" />
		<origin/>
	</inertial>
	<visual>
	<origin xyz="0 0 0" rpy="1.15 1.57 3.78" />	
	<material name="grey" >
      <color rgba=".2 .2 .2 .2" />
  </material>	
	<geometry>
		<mesh filename="package://sparky_model/meshes/Shoulders.stl"/>
	</geometry>
	</visual>
	    <collision>
      <origin xyz="0 0 0" rpy="0 0 0 " />
      <geometry name="shoulders">
		<mesh filename="package://sparky_model/meshes/Shoulders.stl"/>
      </geometry>
    </collision>

</link>

  <gazebo reference="shoulders">
<material>Gazebo/FlatBlack</material>
    <turnGravityOff>true</turnGravityOff>
  </gazebo>




<link name="centerplate">

<inertial>
		<mass value="5"/>
		<inertia ixx="100" ixy="0" ixz="0" iyy="100" iyz="0" izz="100" />
		<origin/>
	</inertial>
	<visual>
	<origin xyz="0 0 0" rpy="0 0 0" />
		 <material name="grey" >
      <color rgba=".2 .2 .2 .2" />
  </material>
	<geometry>
		<mesh filename="package://sparky_model/meshes/CenterPlate.stl"/>
	</geometry>
	</visual>
	    <collision>
      <origin xyz="0 0 0" rpy="0 0 0 " />
      <geometry name="centerplate">
		<mesh filename="package://sparky_model/meshes/CenterPlate.stl"/>
      </geometry>
    </collision>

</link>

  <gazebo reference="centerplate">
<material>Gazebo/Black</material>
    <turnGravityOff>true</turnGravityOff>
  </gazebo>


<link name="stand">

<inertial>
		<mass value="5"/>
		<inertia ixx="100" ixy="0" ixz="0" iyy="100" iyz="0" izz="100" />
		<origin/>
	</inertial>
	<visual>
	<origin xyz="0 0 0" rpy="0 0 -1.57" />
		 <material name="grey" >
      <color rgba=".2 .2 .2 .2" />
  </material>
	<geometry>
		<mesh filename="package://sparky_model/meshes/Stand.stl"/>
	</geometry>
	</visual>
	    <collision>
      <origin xyz="0 0 0" rpy="0 0 0 " />
      <geometry name="stand">
        <mesh filename="package://sparky_model/meshes/Stand.stl" />
      </geometry>
    </collision>

</link>	

  <gazebo reference="stand">
<material>Gazebo/Black</material>
    <turnGravityOff>true</turnGravityOff>
  </gazebo>
  
  	<joint name="standWorld_joint" type="fixed">
		<parent link="world"/>
		<origin xyz="0 0 13" rpy="0 0 0"/>
		<child link="stand"/>
	</joint>
	
<link name="hips">

<inertial>
		<mass value="5"/>
		<inertia ixx="100" ixy="0" ixz="0" iyy="100" iyz="0" izz="100" />
		<origin/>
	</inertial>
	<visual>
	<origin xyz="0 0 0" rpy="0 1.57 1.57" />
		<material name="grey" >
      <color rgba=".2 .2 .2 .2" />
  </material>	
	<geometry>
		<mesh filename="package://sparky_model/meshes/Hips.stl"/>
	</geometry>
	</visual>
	    <collision>
      <origin xyz="0 0 0" rpy="0 0 0 " />
      <geometry name="hips">
		<mesh filename="package://sparky_model/meshes/Hips.stl"/>
      </geometry>
    </collision>

</link>
  <gazebo reference="hips">
<material>Gazebo/Black</material>
    <turnGravityOff>true</turnGravityOff>
  </gazebo>



<joint name="hipjoint" type="fixed">
	<origin xyz="-.1 .7 -.5" rpy="0 0 0"/>
	<parent link="stand"/>
	<child link="hips"/>
</joint>


<!--
-----------------------------Sparky NECK ------------------------------
-->

<link name="throat">

	<inertial>
		<mass value="2.2"/>
		<inertia ixx="100" ixy="0" ixz="0" iyy="100" iyz="0" izz="100" />
		<origin/>
	</inertial>
	<visual>
	<origin xyz="0 0 0" rpy="0 1.57 0" />
		 <material name="grey" >
      <color rgba=".2 .2 .2 .2" />
  </material>
	<geometry>
		<mesh filename="package://sparky_model/meshes/neck.stl" />
	</geometry>
	</visual>
	    <collision>
      <origin xyz="0 0 0" rpy="0 0 0 " />
      <geometry name="throat">
		<mesh filename="package://sparky_model/meshes/neck.stl" />
      </geometry>
    </collision>

</link>

  <gazebo reference="throat">
<material>Gazebo/Black</material>
    <turnGravityOff>true</turnGravityOff>
  </gazebo>


<joint name="HeadNod" type="revolute">
	<origin xyz="0 0 2.53" rpy=".28 0 0"/>
	<axis xyz="1 0 0" /> 
		  <limit upper=".785" lower="-.279" effort="10" velocity="3" />
	<parent link="throat"/>
	<child link="head"/>
</joint>

<joint name="HeadTurn" type="revolute">
	<origin xyz="0 0 0" rpy="0 0 0"/>
	<axis xyz="0 0 1" /> 
	 <limit upper=".785" lower="-.436" effort="10" velocity="3" />
	<parent link="shoulders"/>
	<child link="throat"/>
</joint>

<!--
-----------------------------Sparky HEAD ------------------------------
-->

<link name="head">

	<inertial>
		<mass value="2.2"/>
		<inertia ixx="100" ixy="0" ixz="0" iyy="100" iyz="0" izz="100" />
		<origin/>
	</inertial>
	<visual>
	<origin xyz="0 -2.5 1" rpy="1.57 0 1.57" />
  <material name="grey" >
  </material>
	<geometry>
		<mesh filename="package://sparky_model/meshes/Head2.stl" />
	</geometry>
	</visual>
	    <collision>
      <origin xyz="0 0 0" rpy="0 0 0 " />
      <geometry name="head">
		<mesh filename="package://sparky_model/meshes/Head2.stl" />
      </geometry>
    </collision>

</link>
  <gazebo reference="head">
<material>Gazebo/Black</material>
    <turnGravityOff>true</turnGravityOff>
  </gazebo>


<link name="lowerjaw">

	<inertial>
		<mass value="2.2"/>
		<inertia ixx="100" ixy="0" ixz="0" iyy="100" iyz="0" izz="100" />
		<origin/>
	</inertial>
	<visual>
	<origin xyz="0 -2.65 -2.15" rpy="0 1.57 0" />
	 <material name="grey" >
      <color rgba=".2 .2 .2 .2" />
  </material>
	<geometry>
		<mesh filename="package://sparky_model/meshes/Jaw.stl" />
	</geometry>
	</visual>
	    <collision>
      <origin xyz="0 0 0" rpy="0 0 0 " />
      <geometry name="lowerjaw">
		<mesh filename="package://sparky_model/meshes/Jaw.stl" />
      </geometry>
    </collision>

</link>

  <gazebo reference="lowerjaw">
<material>Gazebo/Black</material>
    <turnGravityOff>true</turnGravityOff>
  </gazebo>

<joint name="Mouth" type="continuous">
	<origin xyz="0 .3 0" rpy="1.19 0 0"/>
		<axis xyz="1 0 0 " /> 
	<parent link="head"/>
	<child link="lowerjaw"/>
</joint>



<!--
-----------------------------Sparky EYES ------------------------------
-->

<link name="Reye">

	<inertial>
		<mass value="2.2"/>
		<inertia ixx="100" ixy="0" ixz="0" iyy="100" iyz="0" izz="100" />
		<origin/>
	</inertial>
	<visual>
	<origin xyz="0 0 0" rpy="1.57 3.14 0" />
		<material name="white" >
			<color rgba="1 1 1 1" />
		</material>
	<geometry>
		<mesh filename="package://sparky_model/meshes/Eye.stl"  />
	</geometry>
	</visual>
	    <collision>
      <origin xyz="0 0 0" rpy="0 0 0 " />
      <geometry name="my_box_collision_geom">
        <box size="0.01 0.015 0.01" />
      </geometry>
    </collision>

</link>

  <gazebo reference="Reye">
<material>Gazebo/White</material>
    <turnGravityOff>true</turnGravityOff>
  </gazebo>

<joint name="EyesLtRt" type="continuous">
	<origin xyz=".6 1.43 .82" rpy="0 0 0"/>
	<axis xyz="0 0 1" /> 
	<limit upper=".8" lower="-.8" effort="10" velocity="3" />
	<parent link="head"/>
	<child link="Reye"/>

</joint>

<link name="Leye">

	<inertial>
		<mass value="2.2"/>
		<inertia ixx="100" ixy="0" ixz="0" iyy="100" iyz="0" izz="100" />
		<origin/>
	</inertial>
	<visual>
	<origin xyz="0 0 0" rpy="1.57 3.14 0" />
		    <material name="white" >
      <color rgba="1 1 1 1" />
  </material>
	<geometry>
		<mesh filename="package://sparky_model/meshes/Eye.stl"  />
	</geometry>
	</visual>
	    <collision>
      <origin xyz="0 0 0" rpy="0 0 0 " />
      <geometry name="my_box_collision_geom">
        <box size="0.01 0.015 0.01" />
      </geometry>
    </collision>

</link>

  <gazebo reference="Leye">
<material>Gazebo/White</material>
    <turnGravityOff>true</turnGravityOff>
  </gazebo>

<joint name="ReyeJoint" type="continuous">
	<origin xyz="-.6 1.43 .82" rpy="0 0 0"/>
	<axis xyz="0 0 1" /> 
	<limit upper=".8" lower="-.8" effort="10" velocity="3" />
	<parent link="head"/>
	<child link="Leye"/>

</joint>

<link name="LLid">

	<inertial>
		<mass value="2.2"/>
		<inertia ixx="100" ixy="0" ixz="0" iyy="100" iyz="0" izz="100" />
		<origin/>
	</inertial>
	<visual>
	<origin xyz="-.03 .4 0" rpy="0 0 -1.57" />
		<material name="Gold" >
			<color rgba=".7 .5 0 1" />
		</material>
	<geometry>
		<mesh filename="package://sparky_model/meshes/EyeLid.stl"  />
	</geometry>
	</visual>
	    <collision>
      <origin xyz="0 0 0" rpy="0 0 0 " />
      <geometry name="my_box_collision_geom">
        <box size="0.01 0.015 0.01" />
      </geometry>
    </collision>

</link>

  <gazebo reference="LLid">
<material>Gazebo/Gold</material>
    <turnGravityOff>true</turnGravityOff>
  </gazebo>

<joint name="EyeBlink" type="continuous">
	<origin xyz="-.6 1.43 .82" rpy="1.57 0 0"/>
	<axis xyz="1 0 0" /> 
	  <limit upper="1.4" lower="0" effort="10" velocity="3" />	
	<parent link="head"/>
	<child link="LLid"/>
</joint>

<link name="RLid">

	<inertial>
		<mass value="2.2"/>
		<inertia ixx="100" ixy="0" ixz="0" iyy="100" iyz="0" izz="100" />
		<origin/>
	</inertial>
	<visual>
	<origin xyz=".03 .4 0" rpy="0 0 -1.57" />
			<material name="Gold" />
	<geometry>
		<mesh filename="package://sparky_model/meshes/EyeLid.stl"  />
	</geometry>
	</visual>
	    <collision>
      <origin xyz="0 0 0" rpy="0 0 0 " />
      <geometry name="my_box_collision_geom">
        <box size="0.01 0.015 0.01" />
      </geometry>
    </collision>

</link>

  <gazebo reference="RLid">
<material>Gazebo/Gold</material>
    <turnGravityOff>true</turnGravityOff>
  </gazebo>

<joint name="RLidJoint" type="continuous">
	<origin xyz=".6 1.43 .82" rpy="1.57 0 0"/>
	<axis xyz="1 0 0" /> 
	<limit upper="1.4" lower="0" effort="10" velocity="3" />
	<parent link="head"/>
	<child link="RLid"/>
</joint>

<link name="RPupil">

	<inertial>
		<mass value="2.2"/>
		<inertia ixx="100" ixy="0" ixz="0" iyy="100" iyz="0" izz="100" />
		<origin/>
	</inertial>
	<visual>
	<origin xyz="0 .3 0" rpy="0 0 0" />
		<material name="Black" >
			<color rgba="0 0 0 0" />
		</material>
	<geometry>
		<sphere radius=".1" />
	</geometry>
	</visual>
	    <collision>
      <origin xyz="0 0 0" rpy="0 0 0 " />
      <geometry name="my_box_collision_geom">
        <box size="0.01 0.015 0.01" />
      </geometry>
    </collision>

</link>

  <gazebo reference="RPupil">
<material>Gazebo/Black</material>
    <turnGravityOff>true</turnGravityOff>
  </gazebo>

<joint name="RPJoint" type="fixed">
	<origin xyz="0 0 0" rpy="0 0 0"/>
	<parent link="Reye"/>
	<child link="RPupil"/>
</joint>
	
<link name="LPupil">

	<inertial>
		<mass value="2.2"/>
		<inertia ixx="100" ixy="0" ixz="0" iyy="100" iyz="0" izz="100" />
		<origin/>
	</inertial>
	<visual>
	<origin xyz="0 .3 0" rpy="0 0 0" />
		<material name="Black" >
			<color rgba="0 0 0 0" />
		</material>
	<geometry>
		<sphere radius=".1" />
	</geometry>
	</visual>
	    <collision>
      <origin xyz="0 0 0" rpy="0 0 0 " />
      <geometry name="my_box_collision_geom">
        <box size="0.01 0.015 0.01" />
      </geometry>
    </collision>

</link>

  <gazebo reference="LPupil">
<material>Gazebo/Black</material>
    <turnGravityOff>true</turnGravityOff>
  </gazebo>

<joint name="LPJoint" type="fixed">
	<origin xyz="0 0 0" rpy="0 0 0"/>
	<parent link="Leye"/>
	<child link="LPupil"/>	
</joint>



<link name="RIris">
	<inertial>
		<mass value="2.2"/>
		<inertia ixx="100" ixy="0" ixz="0" iyy="100" iyz="0" izz="100" />
		<origin/>
	</inertial>
	<visual>
	<origin xyz="0 .22 0" rpy="0 0 0" />
		<material name="LightBlue" >
			<color rgba="0 .4 .4 0" />
		</material>
	<geometry>
		<sphere radius=".15" />
	</geometry>
	</visual>
	<collision>
      <origin xyz="0 0 0" rpy="0 0 0 " />
      <geometry name="iris">
		<sphere radius=".2" />
      </geometry>
    </collision>
</link>

  <gazebo reference="RIris">
<material>Gazebo/Blue</material>
    <turnGravityOff>true</turnGravityOff>
  </gazebo>
	
<link name="LIris">

	<inertial>
		<mass value="2.2"/>
		<inertia ixx="100" ixy="0" ixz="0" iyy="100" iyz="0" izz="100" />
		<origin/>
	</inertial>
	<visual>
	<origin xyz="0 .22 0" rpy="0 0 0" />
		<material name="LightBlue" >

		</material>
	<geometry>
		<sphere radius=".15" />
	</geometry>
	</visual>
		<collision>
      <origin xyz="0 0 0" rpy="0 0 0 " />
      <geometry name="iris">
		<sphere radius=".15" />
      </geometry>
    </collision>
</link>

  <gazebo reference="LIris">
	<material>Gazebo/Blue</material>
    <turnGravityOff>true</turnGravityOff>
  </gazebo>


<joint name="RIrJoint" type="fixed">
	<origin xyz="0 0 0" rpy="0 0 0"/>
	<parent link="Reye"/>
	<child link="RIris"/>
</joint>

<joint name="LIrJoint" type="fixed">
	<origin xyz="0 0 0" rpy="0 0 0"/>
	<parent link="Leye"/>
	<child link="LIris"/>	
</joint>

<link name="EyeLPin">

	<inertial>
		<mass value="2.2"/>
		<inertia ixx="100" ixy="0" ixz="0" iyy="100" iyz="0" izz="100" />
		<origin/>
	</inertial>
	<visual>
	<origin xyz="0 0 0" rpy="-1.57 1.57 0" />
			<material name="grey" />
	<geometry>
		<mesh filename="package://sparky_model/meshes/EyeLPin.stl" />
	</geometry>
	</visual>
	  <collision>
      <origin xyz="0 0 0" rpy="0 0 0 " />
      <geometry name="my_box_collision_geom">
        <box size="0.01 0.015 0.01" />
      </geometry>
    </collision>
</link>

  <gazebo reference="EyeLPin">
<material>Gazebo/Black</material>
    <turnGravityOff>true</turnGravityOff>
  </gazebo>


<link name="EyeBeam">

	<inertial>
		<mass value="2.2"/>
		<inertia ixx="100" ixy="0" ixz="0" iyy="100" iyz="0" izz="100" />
		<origin/>
	</inertial>
	<visual>
	<origin xyz="0 0 0" rpy="0 0 0" />
			<material name="grey" />
	<geometry>
		<mesh filename="package://sparky_model/meshes/EyeBeam.stl" />
	</geometry>
	</visual>
		  <collision>
      <origin xyz="0 0 0" rpy="0 0 0 " />
      <geometry name="eyebeam">
		<mesh filename="package://sparky_model/meshes/EyeBeam.stl" />
      </geometry>
    </collision>
</link>

  <gazebo reference="EyeBeam">
<material>Gazebo/Black</material>
    <turnGravityOff>true</turnGravityOff>
  </gazebo>
	
	<link name="EyeBallPin">

	<inertial>
		<mass value="2.2"/>
		<inertia ixx="100" ixy="0" ixz="0" iyy="100" iyz="0" izz="100" />
		<origin/>
	</inertial>
	<visual>
	<origin xyz=".25 -1.31 -.066" rpy="1.57 0 2.15" />
	<material name="whitegray" >
      <color rgba=".8 .8 .8 .8" />
  </material>
	<geometry>
		<mesh filename="package://sparky_model/meshes/EyeBallPin.stl" />
	</geometry>
	</visual>
		  <collision>
      <origin xyz="0 0 0" rpy="0 0 0 " />
      <geometry name="eyeballpin">
		<mesh filename="package://sparky_model/meshes/EyeBallPin.stl" />
      </geometry>
    </collision>
</link>

  <gazebo reference="EyeBallPin">
<material>Gazebo/White</material>
    <turnGravityOff>true</turnGravityOff>
  </gazebo>

	<link name="EyeBallPin2">

	<inertial>
		<mass value="2.2"/>
		<inertia ixx="100" ixy="0" ixz="0" iyy="100" iyz="0" izz="100" />
		<origin/>
	</inertial>
	<visual>
	<origin xyz=".25 -1.31 -.066" rpy="1.57 0 2.12" />
			<material name="whitegray" />
	<geometry>
		<mesh filename="package://sparky_model/meshes/EyeBallPin.stl" />
	</geometry>
	</visual>
		  <collision>
      <origin xyz="0 0 0" rpy="0 0 0 " />
      <geometry name="eyeballpin">
		<mesh filename="package://sparky_model/meshes/EyeBallPin.stl" />
      </geometry>
    </collision>
</link>

  <gazebo reference="EyeBallPin2">
<material>Gazebo/White</material>
    <turnGravityOff>true</turnGravityOff>
  </gazebo>

<joint name="LPinJoint" type="continuous">
	<origin xyz="0 .7 1.25" rpy="0 0 0"/>
	<axis xyz="0 1 0" /> 

	<parent link="head"/>
	<child link="EyeLPin"/>
</joint>

<joint name="EyeBeamJoint" type="prismatic">
	<origin xyz=".055 .85 .6" rpy="0 0 0"/>
	<axis xyz="1 0 0" /> 
	<limit upper="2" lower="-2" effort="10" velocity="3" />
	<parent link="head"/>
	<child link="EyeBeam"/>
</joint>

<joint name="EyeBallPinJoint" type="revolute">
	<origin xyz=".6 0 0" rpy="0 0 0"/>
	<axis xyz="0 0 1" /> 
	<limit upper=".698" lower="-.524" effort="10" velocity="3" />
	<parent link="EyeBeam"/>
	<child link="EyeBallPin"/>
</joint>

<joint name="EyeBallPinJoint2" type="revolute">
	<origin xyz="-.6 0 0" rpy="0 0 0"/>
	<axis xyz="0 0 1" /> 
	<limit upper=".698" lower="-.524" effort="10" velocity="3" />
	<parent link="EyeBeam"/>
	<child link="EyeBallPin2"/>
</joint>

<!--
-----------------------Sparky  Right ARM ---------------------
-->

<link name="rightbicept" >

<inertial>
		<mass value="5"/>
		<inertia ixx="100" ixy="0" ixz="0" iyy="100" iyz="0" izz="100" />
		<origin/>
	</inertial>
	<visual>
	<origin xyz="0 .15 -.5" rpy="1.63 -.08 -1.57" />
	<material name="grey" >
      <color rgba=".2 .2 .2 .2" />
  </material>
	<geometry>
		<mesh filename="package://sparky_model/meshes/RightBicept.stl"  />
	</geometry>
	</visual>
	    <collision>
      <origin xyz="0 0 0" rpy="0 0 0 " />
      <geometry name="my_box_collision_geom">
        <box size="0.01 0.015 0.01" />
      </geometry>
    </collision>

</link>

  <gazebo reference="rightbicept">
<material>Gazebo/Black</material>
    <turnGravityOff>true</turnGravityOff>
  </gazebo>

<link name="rightshoulderball" >

<inertial>
		<mass value="5"/>
		<inertia ixx="100" ixy="0" ixz="0" iyy="100" iyz="0" izz="100" />
		<origin/>
	</inertial>
	<visual>
	<origin xyz=".53 0 -.1" rpy="4 1.57 .35" />
		<material name="grey" >
      <color rgba=".2 .2 .2 .2" />
  </material>
	<geometry>
		<mesh filename="package://sparky_model/meshes/ShoulderConnecter.stl"  />
	</geometry>
	</visual>
	    <collision>
      <origin xyz="0 0 0" rpy="0 0 0 " />
      <geometry name="my_box_collision_geom">
        <box size="0.01 0.015 0.01" />
      </geometry>
    </collision>

</link>

  <gazebo reference="rightshoulderball">
<material>Gazebo/Black</material>
    <turnGravityOff>true</turnGravityOff>
  </gazebo>

<joint name="RtArmForward" type="revolute">
	<origin xyz="2.67 -.2 .1" rpy="0 0 0"/>
	<axis xyz="1 0 0" /> 
	  <limit upper="4" lower="0" effort="10" velocity="3" />
	<parent link="shoulders"/>
	<child link="rightshoulderball"/>
</joint>

<joint name="RtArmOut" type="continuous">
	<origin xyz="0 0 0" rpy=".28 0 0"/>
	<axis xyz="0 1 0" /> 
	<parent link="rightshoulderball"/>
	<child link="rightbicept"/>
</joint>

<link name="rightforearm" >

<inertial>
		<mass value="5"/>
		<inertia ixx="100" ixy="0" ixz="0" iyy="100" iyz="0" izz="100" />
		<origin/>
	</inertial>
	<visual>
	<origin xyz=".2 3 .08" rpy="0 3.92 0" />
		<material name="grey" >
      <color rgba=".2 .2 .2 .2" />
  </material>
	<geometry>
		<mesh filename="package://sparky_model/meshes/RightForearm.stl"  />
	</geometry>
	</visual>
	    <collision>
      <origin xyz="0 0 0" rpy="0 0 0 " />
      <geometry name="my_box_collision_geom">
        <box size="0.01 0.015 0.01" />
      </geometry>
    </collision>

</link>

  <gazebo reference="rightforearm">
<material>Gazebo/Black</material>
    <turnGravityOff>true</turnGravityOff>
  </gazebo>

<joint name="RtElbow" type="continuous">
	<origin xyz="0 -.2 -3.5" rpy="1.8 0 .785"/>
	<axis xyz="1 0 0" /> 
	<parent link="rightbicept"/>
	<child link="rightforearm" />

</joint>

<link name="righthand" >

<inertial>
		<mass value="5"/>
		<inertia ixx="100" ixy="0" ixz="0" iyy="100" iyz="0" izz="100" />
		<origin/>
	</inertial>
	<visual>
	<origin xyz="0 .9 -.52" rpy="-1.57 0 1.57" />
	<material name="whitegray" >
      <color rgba=".8 .8 .8 .8" />
  </material>
	<geometry>
		<mesh filename="package://sparky_model/meshes/RightHand.stl"   />
	</geometry>
	</visual>
	    <collision>
      <origin xyz="0 0 0" rpy="0 0 0 " />
      <geometry name="my_box_collision_geom">
        <box size="0.01 0.015 0.01" />
      </geometry>
    </collision>

</link>

  <gazebo reference="righthand">
<material>Gazebo/White</material>
    <turnGravityOff>true</turnGravityOff>
  </gazebo>

<joint name="RtWrist" type="continuous">
	<origin xyz=".12 -3.6 .95" rpy ="-1.8 0 0" />
	<axis xyz="1 0 0" /> 
	<parent link="rightforearm"/>
	<child link="righthand" />

</joint>



<!--
-----------------------Sparky LEFT ARM ---------------------
-->

<link name="leftbicept" >

<inertial>
		<mass value="5"/>
		<inertia ixx="100" ixy="0" ixz="0" iyy="100" iyz="0" izz="100" />
		<origin/>
	</inertial>
	<visual>
	<origin xyz=".2 .2 -.5" rpy="-1.53 3.2 0" />
		 <material name="grey" >
      <color rgba=".2 .2 .2 .2" />
  </material>
	<geometry>
		<mesh filename="package://sparky_model/meshes/LeftBicept.stl"  />
	</geometry>
	</visual>
	    <collision>
      <origin xyz="0 0 0" rpy="0 0 0 " />
      <geometry name="my_box_collision_geom">
        <box size="0.01 0.015 0.01" />
      </geometry>
    </collision>

	
</link>

  <gazebo reference="leftbicept">
<material>Gazebo/Black</material>
    <turnGravityOff>true</turnGravityOff>
  </gazebo>

<link name="leftshoulderball" >

<inertial>
		<mass value="5"/>
		<inertia ixx="100" ixy="0" ixz="0" iyy="100" iyz="0" izz="100" />
		<origin/>
	</inertial>
	<visual>
	<origin xyz="2.8 .15 -.15" rpy=".4 -1.57 .15" />
		 <material name="grey" >
      <color rgba=".2 .2 .2 .2" />
  </material>
	<geometry>
		<mesh filename="package://sparky_model/meshes/LeftShoulderConnecter.stl"  />
	</geometry>
	</visual>
	    <collision>
      <origin xyz="0 0 0" rpy="0 0 0 " />
      <geometry name="my_box_collision_geom">
        <box size="0.01 0.015 0.01" />
      </geometry>
    </collision>

</link>

  <gazebo reference="leftshoulderball">
<material>Gazebo/Black</material>
    <turnGravityOff>true</turnGravityOff>
  </gazebo>


<joint name="LtArmOut" type="continuous">
	<origin xyz="-2.67 .2 .05" rpy="3.14 0 0"/>
	<axis xyz="1 0 0" /> 
	<parent link="shoulders"/>
	<child link="leftshoulderball"/>
</joint>

<joint name="LtArmForward" type="continuous">
	<origin xyz="0 0 0" rpy="3.42 0 0"/>
	<axis xyz="0 1 0" /> 
	<parent link="leftshoulderball"/>
	<child link="leftbicept"/>
</joint>

<link name="leftforearm" >

<inertial>
		<mass value="5"/>
		<inertia ixx="100" ixy="0" ixz="0" iyy="100" iyz="0" izz="100" />
		<origin/>
	</inertial>
	<visual>
	<origin xyz="-1.05 6.6 0" rpy="0 2.355 .3" />
	<material name="grey" >
      <color rgba=".2 .2 .2 .2" />
  </material>
	<geometry>
		<mesh filename="package://sparky_model/meshes/LeftForearm.stl"  />
	</geometry>
	</visual>
	    <collision>
      <origin xyz="0 0 0" rpy="0 0 0 " />
      <geometry name="my_box_collision_geom">
        <box size="0.01 0.015 0.01" />
      </geometry>
    </collision>

</link>

  <gazebo reference="leftforearm">
<material>Gazebo/Black</material>
    <turnGravityOff>true</turnGravityOff>
  </gazebo>

<joint name="LtElbow" type="continuous">
	<parent link="leftbicept" />
	<child link="leftforearm" />
	<origin xyz="0 .1 -3.51" rpy="-1.57 0 .785" />
	<axis xyz="0 0 1" /> 
</joint>

<link name="lefthand" >

<inertial>
		<mass value="5"/>
		<inertia ixx="100" ixy="0" ixz="0" iyy="100" iyz="0" izz="100" />
		<origin/>
	</inertial>
	<visual>
	<origin xyz="-.85 0 -.5" rpy="-1.57 0 3.14" />
	<material name="whitegray" >
      <color rgba=".8 .8 .8 .8" />
  </material>
	<geometry>
		<mesh filename="package://sparky_model/meshes/LeftHand.stl"  />
	</geometry>
	</visual>
	    <collision>
      <origin xyz="0 0 0" rpy="0 0 0 " />
      <geometry name="my_box_collision_geom">
        <box size="0.01 0.015 0.01" />
      </geometry>
    </collision>

</link>

  <gazebo reference="lefthand">
<material>Gazebo/White</material>
    <turnGravityOff>true</turnGravityOff>
  </gazebo>

<joint name="LtWrist" type="continuous">
	<origin xyz="-.18 3.71 0.05" rpy="1.57 0 0" />
	<axis xyz="0 1 0" /> 
	<parent link="leftforearm"/>
	<child link="lefthand" />

</joint>


<!--
-----------------------Sparky RIGHT LEG ---------------------
-->

<link name="rightthigh" >

<inertial>
		<mass value="5"/>
		<inertia ixx="100" ixy="0" ixz="0" iyy="100" iyz="0" izz="100" />
		<origin/>
	</inertial>
	<visual>
	<origin xyz="-1.3 -.89 .37" rpy="-.05 .3 -1.57" />
	<material name="grey" >
      <color rgba=".2 .2 .2 .2" />
  </material>
	<geometry>
		<mesh filename="package://sparky_model/meshes/Thigh.stl"  />
	</geometry>
	</visual>
	    <collision>
      <origin xyz="0 0 0" rpy="0 0 0 " />
      <geometry name="rightthigh">
		<mesh filename="package://sparky_model/meshes/Thigh.stl"  />
      </geometry>
    </collision>

</link>

  <gazebo reference="rightthigh">
<material>Gazebo/Black</material>
    <turnGravityOff>true</turnGravityOff>
  </gazebo>

<link name="rightcalf" >

<inertial>
		<mass value="5"/>
		<inertia ixx="100" ixy="0" ixz="0" iyy="100" iyz="0" izz="100" />
		<origin/>
	</inertial>
	<visual>
	<origin xyz="-1.6 4.7 2.05" rpy="0 -1 -1.57" />
	<material name="grey" >
      <color rgba=".2 .2 .2 .2" />
  </material>
	<geometry>
		<mesh filename="package://sparky_model/meshes/Calf.stl"  />
	</geometry>
	</visual>
		    <collision>
      <origin xyz="0 0 0" rpy="0 0 0 " />
      <geometry name="rightcalf">
		<mesh filename="package://sparky_model/meshes/Calf.stl"  />
      </geometry>
    </collision>

</link>

  <gazebo reference="rightcalf">
<material>Gazebo/Black</material>
    <turnGravityOff>true</turnGravityOff>
  </gazebo>

<link name="rightfoot">

<inertial>
		<mass value="5"/>
		<inertia ixx="100" ixy="0" ixz="0" iyy="100" iyz="0" izz="100" />
		<origin/>
	</inertial>
	<visual>
	<origin xyz="3.6 0 -.5" rpy="0 0 -1.57" />
	<material name="whitegray" >
	       <color rgba=".2 .2 .2 .2" />
	       </material>
	<geometry>
		<mesh filename="package://sparky_model/meshes/RightFoot.stl"  />
	</geometry>
	</visual>
	    <collision>
      <origin xyz="0 0 0" rpy="0 0 0 " />
      <geometry name="rightfoot">
		<mesh filename="package://sparky_model/meshes/RightFoot.stl"  />
      </geometry>
    </collision>

	
</link>

  <gazebo reference="rightfoot">
<material>Gazebo/White</material>
    <turnGravityOff>true</turnGravityOff>
  </gazebo>

<joint name="RtFootForward" type="continuous">
	<parent link="hips"/>
	<child link="rightthigh" />
	<origin xyz="1.5 0 0" rpy="0 -.05 0"/>
	<axis xyz="1.05 0 0" /> 
</joint>

<joint name="RtFootUp" type="continuous" >
	<parent link="rightthigh" />
	<child link="rightcalf" />
	<origin xyz="0 0 -5.0" rpy="-.23 .05 0" />
	<axis xyz="1.23 -.05 0" /> 
</joint>

<joint name="RtFootjoint" type="fixed">
	<parent link="rightcalf" />
	<child link="rightfoot" />
	<origin xyz="0 .8 -4.3" rpy="-.2 0 0" />
	<axis xyz="1 0 0" /> 
</joint>


<!--
-----------------------Sparky LEFT LEG ---------------------
-->

<link name="leftthigh">

<inertial>
		<mass value="5"/>
		<inertia ixx="100" ixy="0" ixz="0" iyy="100" iyz="0" izz="100" />
		<origin/>
	</inertial>
	<visual>
	<origin xyz="-1.3 -.89 .37" rpy="-.05 .3 -1.57" />
	<material name="grey" >
       <color rgba=".2 .2 .2 .2" />
  </material>
	<geometry>
		<mesh filename="package://sparky_model/meshes/Thigh.stl"  />
	</geometry>
	</visual>
	    <collision>
      <origin xyz="0 0 0" rpy="0 0 0 " />
      <geometry name="leftthigh">
		<mesh filename="package://sparky_model/meshes/Thigh.stl"  />
      </geometry>
    </collision>

	
</link>

  <gazebo reference="leftthigh">
<material>Gazebo/Black</material>
    <turnGravityOff>true</turnGravityOff>
  </gazebo>

<link name="leftcalf">

<inertial>
		<mass value="5"/>
		<inertia ixx="100" ixy="0" ixz="0" iyy="100" iyz="0" izz="100" />
		<origin/>
	</inertial>
	<visual>
	<origin xyz="-1.6 4.7 2.05" rpy="0 -1 -1.57" />
	<material name="grey" >
      <color rgba=".2 .2 .2 .2" />
  </material>
	<geometry>
		<mesh filename="package://sparky_model/meshes/Calf.stl"  />
	</geometry>
	</visual>
	    <collision>
      <origin xyz="0 0 0" rpy="0 0 0 " />
      <geometry name="leftcalf">
		<mesh filename="package://sparky_model/meshes/Calf.stl"  />
      </geometry>
    </collision>

	
</link>

  <gazebo reference="leftcalf">
<material>Gazebo/Black</material>
    <turnGravityOff>true</turnGravityOff>
  </gazebo>


<link name="leftfoot">

<inertial>
		<mass value="5"/>
		<inertia ixx="100" ixy="0" ixz="0" iyy="100" iyz="0" izz="100" />
		<origin/>
	</inertial>
	<visual>
	<origin xyz="0 0 -.5" rpy="0 0 -1.57" />
	<material name="whitegray" />
	<geometry>
		<mesh filename="package://sparky_model/meshes/LeftFoot.stl"  />
	</geometry>
	</visual>
	    <collision>
      <origin xyz="0 0 0" rpy="0 0 0 " />
      <geometry name="leftfoot">
		<mesh filename="package://sparky_model/meshes/LeftFoot.stl"  />
      </geometry>
    </collision>

	
</link>

  <gazebo reference="leftfoot">
<material>Gazebo/White</material>
    <turnGravityOff>true</turnGravityOff>
  </gazebo>

<joint name="LtFootForward" type="continuous">
	<parent link="hips"/>
	<child link="leftthigh"/>
	<origin xyz="-1.65 0 0" rpy="0 -.05 0"/>
	<axis xyz="1.05 0 0" /> 
</joint>

<joint name="LtFootUp" type="continuous">
	<parent link="leftthigh" />
	<child link="leftcalf" />
	<origin xyz="0 0 -5" rpy="-.23 .05 0" />
	<axis xyz="1.23 -.05 0" /> 
</joint>

<joint name="LtFootjoint" type="fixed">
	<parent link="leftcalf" />
	<child link="leftfoot" />
	<origin xyz="0 .8 -4.3" rpy="-.2 0 0" />
	<axis xyz="1 0 0" /> 
</joint>



<!--
-----------------------------Sparky Upper Spine ------------------------------
-->



<link name="TS1">
<inertial>
		<mass value="5"/>
		<inertia ixx="100" ixy="0" ixz="0" iyy="100" iyz="0" izz="100" />
		<origin/>
	</inertial>
	<visual>
	<origin xyz="0 0 0" rpy="0 0 0" />
	<material name="silver" >
		<color rgba=".5 .5 .5 .5" />
	</material>
	<geometry>
		<cylinder radius=".25" length=".104" />
	</geometry>
	</visual>
		    <collision>
      <origin xyz="0 0 0" rpy="0 0 0 " />
      <geometry name="collision_geom">
        <cylinder radius=".25" length=".104" />
      </geometry>
    </collision>
</link>



<link name="TS2">
<inertial>
		<mass value="5"/>
		<inertia ixx="100" ixy="0" ixz="0" iyy="100" iyz="0" izz="100" />
		<origin/>
	</inertial>
	<visual>
	<origin xyz="0 0 0" rpy="0 0 0" />
	<material name="silver" >
	</material>
	<geometry>
		<cylinder radius=".25" length=".104" />
	</geometry>
	</visual>
		    <collision>
      <origin xyz="0 0 0" rpy="0 0 0 " />
      <geometry name="collision_geom">
        <cylinder radius=".25" length=".104" />
      </geometry>
    </collision>
</link>

<link name="TS3">
<inertial>
		<mass value="5"/>
		<inertia ixx="100" ixy="0" ixz="0" iyy="100" iyz="0" izz="100" />
		<origin/>
	</inertial>
	<visual>
	<origin xyz="0 0 0" rpy="0 0 0" />
	<material name="silver" >
	</material>
	<geometry>
		<cylinder radius=".25" length=".104" />
	</geometry>
	</visual>
		    <collision>
      <origin xyz="0 0 0" rpy="0 0 0 " />
      <geometry name="collision_geom">
        <cylinder radius=".25" length=".104" />
      </geometry>
    </collision>
</link>

<link name="TS4">
<inertial>
		<mass value="5"/>
		<inertia ixx="100" ixy="0" ixz="0" iyy="100" iyz="0" izz="100" />
		<origin/>
	</inertial>
	<visual>
	<origin xyz="0 0 0" rpy="0 0 0" />
	<material name="silver" >
	</material>
	<geometry>
		<cylinder radius=".25" length=".104" />
	</geometry>
	</visual>
		    <collision>
      <origin xyz="0 0 0" rpy="0 0 0 " />
      <geometry name="collision_geom">
        <cylinder radius=".25" length=".104" />
      </geometry>
    </collision>
</link>

<link name="TS5">
<inertial>
		<mass value="5"/>
		<inertia ixx="100" ixy="0" ixz="0" iyy="100" iyz="0" izz="100" />
		<origin/>
	</inertial>
	<visual>
	<origin xyz="0 0 0" rpy="0 0 0" />
	<material name="silver" >
	</material>
	<geometry>
		<cylinder radius=".25" length=".104" />
	</geometry>
	</visual>
		    <collision>
      <origin xyz="0 0 0" rpy="0 0 0 " />
      <geometry name="collision_geom">
        <cylinder radius=".25" length=".104" />
      </geometry>
    </collision>
</link>


<link name="TS6">
<inertial>
		<mass value="5"/>
		<inertia ixx="100" ixy="0" ixz="0" iyy="100" iyz="0" izz="100" />
		<origin/>
	</inertial>
	<visual>
	<origin xyz="0 0 0" rpy="0 0 0" />
	<material name="silver" >
	</material>
	<geometry>
		<cylinder radius=".25" length=".104" />
	</geometry>
	</visual>
		    <collision>
      <origin xyz="0 0 0" rpy="0 0 0 " />
      <geometry name="collision_geom">
        <cylinder radius=".25" length=".104" />
      </geometry>
    </collision>
</link>

<link name="TS7">
<inertial>
		<mass value="5"/>
		<inertia ixx="100" ixy="0" ixz="0" iyy="100" iyz="0" izz="100" />
		<origin/>
	</inertial>
	<visual>
	<origin xyz="0 0 0" rpy="0 0 0" />
	<material name="silver" >
	</material>
	<geometry>
		<cylinder radius=".25" length=".104" />
	</geometry>
	</visual>
		    <collision>
      <origin xyz="0 0 0" rpy="0 0 0 " />
      <geometry name="collision_geom">
        <cylinder radius=".25" length=".104" />
      </geometry>
    </collision>
	
</link>

<link name="TS8">
<inertial>
		<mass value="5"/>
		<inertia ixx="100" ixy="0" ixz="0" iyy="100" iyz="0" izz="100" />
		<origin/>
	</inertial>
	<visual>
	<origin xyz="0 0 0" rpy="0 0 0" />
	<material name="silver" >
	</material>
	<geometry>
		<cylinder radius=".25" length=".104" />
	</geometry>
	</visual>
		    <collision>
      <origin xyz="0 0 0" rpy="0 0 0 " />
      <geometry name="collision_geom">
        <cylinder radius=".25" length=".104" />
      </geometry>
    </collision>
	
</link>

<link name="TS9">
<inertial>
		<mass value="5"/>
		<inertia ixx="100" ixy="0" ixz="0" iyy="100" iyz="0" izz="100" />
		<origin/>
	</inertial>
	<visual>
	<origin xyz="0 0 0" rpy="0 0 0" />
	<material name="silver" >
		<color rgba=".5 .5 .5 .5" />
	</material>
	<geometry>
		<cylinder radius=".25" length=".104" />
	</geometry>
	</visual>
		    <collision>
      <origin xyz="0 0 0" rpy="0 0 0 " />
      <geometry name="collision_geom">
        <cylinder radius=".25" length=".104" />
      </geometry>
    </collision>
</link>



<link name="TS10">
<inertial>
		<mass value="5"/>
		<inertia ixx="100" ixy="0" ixz="0" iyy="100" iyz="0" izz="100" />
		<origin/>
	</inertial>
	<visual>
	<origin xyz="0 0 0" rpy="0 0 0" />
	<material name="silver" >
	</material>
	<geometry>
		<cylinder radius=".25" length=".104" />
	</geometry>
	</visual>
		    <collision>
      <origin xyz="0 0 0" rpy="0 0 0 " />
      <geometry name="collision_geom">
        <cylinder radius=".25" length=".104" />
      </geometry>
    </collision>
</link>

<link name="TS11">
<inertial>
		<mass value="5"/>
		<inertia ixx="100" ixy="0" ixz="0" iyy="100" iyz="0" izz="100" />
		<origin/>
	</inertial>
	<visual>
	<origin xyz="0 0 0" rpy="0 0 0" />
	<material name="silver" >
	</material>
	<geometry>
		<cylinder radius=".25" length=".104" />
	</geometry>
	</visual>
		    <collision>
      <origin xyz="0 0 0" rpy="0 0 0 " />
      <geometry name="collision_geom">
        <cylinder radius=".25" length=".104" />
      </geometry>
    </collision>
</link>

<link name="TS12">
<inertial>
		<mass value="5"/>
		<inertia ixx="100" ixy="0" ixz="0" iyy="100" iyz="0" izz="100" />
		<origin/>
	</inertial>
	<visual>
	<origin xyz="0 0 0" rpy="0 0 0" />
	<material name="silver" >
	</material>
	<geometry>
		<cylinder radius=".25" length=".104" />
	</geometry>
	</visual>
		    <collision>
      <origin xyz="0 0 0" rpy="0 0 0 " />
      <geometry name="collision_geom">
        <cylinder radius=".25" length=".104" />
      </geometry>
    </collision>
</link>

<link name="TS13">
<inertial>
		<mass value="5"/>
		<inertia ixx="100" ixy="0" ixz="0" iyy="100" iyz="0" izz="100" />
		<origin/>
	</inertial>
	<visual>
	<origin xyz="0 0 0" rpy="0 0 0" />
	<material name="silver" >
	</material>
	<geometry>
		<cylinder radius=".25" length=".104" />
	</geometry>
	</visual>
		    <collision>
      <origin xyz="0 0 0" rpy="0 0 0 " />
      <geometry name="collision_geom">
        <cylinder radius=".25" length=".104" />
      </geometry>
    </collision>
</link>

<link name="TS14">
<inertial>
		<mass value="5"/>
		<inertia ixx="100" ixy="0" ixz="0" iyy="100" iyz="0" izz="100" />
		<origin/>
	</inertial>
	<visual>
	<origin xyz="0 0 0" rpy="0 0 0" />
	<material name="silver" >
	</material>
	<geometry>
		<cylinder radius=".25" length=".104" />
	</geometry>
	</visual>
		    <collision>
      <origin xyz="0 0 0" rpy="0 0 0 " />
      <geometry name="collision_geom">
        <cylinder radius=".25" length=".104" />
      </geometry>
    </collision>
</link>

<link name="TS15">
<inertial>
		<mass value="5"/>
		<inertia ixx="100" ixy="0" ixz="0" iyy="100" iyz="0" izz="100" />
		<origin/>
	</inertial>
	<visual>
	<origin xyz="0 0 0" rpy="0 0 0" />
	<material name="silver" >
	</material>
	<geometry>
		<cylinder radius=".25" length=".104" />
	</geometry>
	</visual>
		    <collision>
      <origin xyz="0 0 0" rpy="0 0 0 " />
      <geometry name="collision_geom">
        <cylinder radius=".25" length=".104" />
      </geometry>
    </collision>
	
</link>

<link name="TS16">
<inertial>
		<mass value="5"/>
		<inertia ixx="100" ixy="0" ixz="0" iyy="100" iyz="0" izz="100" />
		<origin/>
	</inertial>
	<visual>
	<origin xyz="0 0 0" rpy="0 0 0" />
	<material name="silver" >
	</material>
	<geometry>
		<cylinder radius=".25" length=".104" />
	</geometry>
	</visual>
		    <collision>
      <origin xyz="0 0 0" rpy="0 0 0 " />
      <geometry name="collision_geom">
        <cylinder radius=".25" length=".104" />
      </geometry>
    </collision>
	
</link>
<link name="TS17">
<inertial>
		<mass value="5"/>
		<inertia ixx="100" ixy="0" ixz="0" iyy="100" iyz="0" izz="100" />
		<origin/>
	</inertial>
	<visual>
	<origin xyz="0 0 0" rpy="0 0 0" />
	<material name="silver" >
		<color rgba=".5 .5 .5 .5" />
	</material>
	<geometry>
		<cylinder radius=".25" length=".104" />
	</geometry>
	</visual>
		    <collision>
      <origin xyz="0 0 0" rpy="0 0 0 " />
      <geometry name="collision_geom">
        <cylinder radius=".25" length=".104" />
      </geometry>
    </collision>
</link>



<link name="TS18">
<inertial>
		<mass value="5"/>
		<inertia ixx="100" ixy="0" ixz="0" iyy="100" iyz="0" izz="100" />
		<origin/>
	</inertial>
	<visual>
	<origin xyz="0 0 0" rpy="0 0 0" />
	<material name="silver" >
	</material>
	<geometry>
		<cylinder radius=".25" length=".104" />
	</geometry>
	</visual>
		    <collision>
      <origin xyz="0 0 0" rpy="0 0 0 " />
      <geometry name="collision_geom">
        <cylinder radius=".25" length=".104" />
      </geometry>
    </collision>
</link>

<link name="TS19">
<inertial>
		<mass value="5"/>
		<inertia ixx="100" ixy="0" ixz="0" iyy="100" iyz="0" izz="100" />
		<origin/>
	</inertial>
	<visual>
	<origin xyz="0 0 0" rpy="0 0 0" />
	<material name="silver" >
	</material>
	<geometry>
		<cylinder radius=".25" length=".104" />
	</geometry>
	</visual>
		    <collision>
      <origin xyz="0 0 0" rpy="0 0 0 " />
      <geometry name="collision_geom">
        <cylinder radius=".25" length=".104" />
      </geometry>
    </collision>
</link>

<link name="TS20">
<inertial>
		<mass value="5"/>
		<inertia ixx="100" ixy="0" ixz="0" iyy="100" iyz="0" izz="100" />
		<origin/>
	</inertial>
	<visual>
	<origin xyz="0 0 0" rpy="0 0 0" />
	<material name="silver" >
	</material>
	<geometry>
		<cylinder radius=".25" length=".104" />
	</geometry>
	</visual>
		    <collision>
      <origin xyz="0 0 0" rpy="0 0 0 " />
      <geometry name="collision_geom">
        <cylinder radius=".25" length=".104" />
      </geometry>
    </collision>
</link>

<link name="TS21">
<inertial>
		<mass value="5"/>
		<inertia ixx="100" ixy="0" ixz="0" iyy="100" iyz="0" izz="100" />
		<origin/>
	</inertial>
	<visual>
	<origin xyz="0 0 0" rpy="0 0 0" />
	<material name="silver" >
	</material>
	<geometry>
		<cylinder radius=".25" length=".104" />
	</geometry>
	</visual>
		    <collision>
      <origin xyz="0 0 0" rpy="0 0 0 " />
      <geometry name="collision_geom">
        <cylinder radius=".25" length=".104" />
      </geometry>
    </collision>
</link>


<link name="TS22">
<inertial>
		<mass value="5"/>
		<inertia ixx="100" ixy="0" ixz="0" iyy="100" iyz="0" izz="100" />
		<origin/>
	</inertial>
	<visual>
	<origin xyz="0 0 0" rpy="0 0 0" />
	<material name="silver" >
	</material>
	<geometry>
		<cylinder radius=".25" length=".104" />
	</geometry>
	</visual>
		    <collision>
      <origin xyz="0 0 0" rpy="0 0 0 " />
      <geometry name="collision_geom">
        <cylinder radius=".25" length=".104" />
      </geometry>
    </collision>
</link>

<link name="TS23">
<inertial>
		<mass value="5"/>
		<inertia ixx="100" ixy="0" ixz="0" iyy="100" iyz="0" izz="100" />
		<origin/>
	</inertial>
	<visual>
	<origin xyz="0 0 0" rpy="0 0 0" />
	<material name="silver" >
	</material>
	<geometry>
		<cylinder radius=".25" length=".104" />
	</geometry>
	</visual>
		    <collision>
      <origin xyz="0 0 0" rpy="0 0 0 " />
      <geometry name="collision_geom">
        <cylinder radius=".25" length=".104" />
      </geometry>
    </collision>
	
</link>

<link name="TS24">
<inertial>
		<mass value="5"/>
		<inertia ixx="100" ixy="0" ixz="0" iyy="100" iyz="0" izz="100" />
		<origin/>
	</inertial>
	<visual>
	<origin xyz="0 0 0" rpy="0 0 0" />
	<material name="silver" >
	</material>
	<geometry>
		<cylinder radius=".25" length=".104" />
	</geometry>
	</visual>
		    <collision>
      <origin xyz="0 0 0" rpy="0 0 0 " />
      <geometry name="collision_geom">
        <cylinder radius=".25" length=".104" />
      </geometry>
    </collision>
	
</link>

  <gazebo reference="TS1">
<material>Gazebo/Grey</material>
    <turnGravityOff>true</turnGravityOff>
  </gazebo>
 
  <gazebo reference="TS2">
<material>Gazebo/Grey</material>
    <turnGravityOff>true</turnGravityOff>
  </gazebo>
 
  <gazebo reference="TS3">
<material>Gazebo/Grey</material>
    <turnGravityOff>true</turnGravityOff>
  </gazebo>
 
  <gazebo reference="TS4">
<material>Gazebo/Grey</material>
    <turnGravityOff>true</turnGravityOff>
  </gazebo>
 
  <gazebo reference="TS5">
<material>Gazebo/Grey</material>
    <turnGravityOff>true</turnGravityOff>
  </gazebo>
 
  <gazebo reference="TS6">
<material>Gazebo/Grey</material>
    <turnGravityOff>true</turnGravityOff>
  </gazebo>
 
  <gazebo reference="TS7">
<material>Gazebo/Grey</material>
    <turnGravityOff>true</turnGravityOff>
  </gazebo>
 
  <gazebo reference="TS8">
<material>Gazebo/Grey</material>
    <turnGravityOff>true</turnGravityOff>
  </gazebo>
 
  <gazebo reference="TS9">
<material>Gazebo/Grey</material>
    <turnGravityOff>true</turnGravityOff>
  </gazebo>
 
  <gazebo reference="TS10">
<material>Gazebo/Grey</material>
    <turnGravityOff>true</turnGravityOff>
  </gazebo>
 
  <gazebo reference="TS11">
<material>Gazebo/Grey</material>
    <turnGravityOff>true</turnGravityOff>
  </gazebo>
 
  <gazebo reference="TS12">
<material>Gazebo/Grey</material>
    <turnGravityOff>true</turnGravityOff>
  </gazebo>
 
  <gazebo reference="TS13">
<material>Gazebo/Grey</material>
    <turnGravityOff>true</turnGravityOff>
  </gazebo>
 
  <gazebo reference="TS14">
<material>Gazebo/Grey</material>
    <turnGravityOff>true</turnGravityOff>
  </gazebo>
 
  <gazebo reference="TS15">
<material>Gazebo/Grey</material>
    <turnGravityOff>true</turnGravityOff>
  </gazebo>
 
  <gazebo reference="TS16">
<material>Gazebo/Grey</material>
    <turnGravityOff>true</turnGravityOff>
  </gazebo>
 
  <gazebo reference="TS17">
<material>Gazebo/Grey</material>
    <turnGravityOff>true</turnGravityOff>
  </gazebo>
 
  <gazebo reference="TS18">
<material>Gazebo/Grey</material>
    <turnGravityOff>true</turnGravityOff>
  </gazebo>
 
  <gazebo reference="TS19">
<material>Gazebo/Grey</material>
    <turnGravityOff>true</turnGravityOff>
  </gazebo>
 
  <gazebo reference="TS20">
<material>Gazebo/Grey</material>
    <turnGravityOff>true</turnGravityOff>
  </gazebo>
 
  <gazebo reference="TS21">
<material>Gazebo/Grey</material>
    <turnGravityOff>true</turnGravityOff>
  </gazebo>
 
  <gazebo reference="TS22">
<material>Gazebo/Grey</material>
    <turnGravityOff>true</turnGravityOff>
  </gazebo>
 
  <gazebo reference="TS23">
<material>Gazebo/Grey</material>
    <turnGravityOff>true</turnGravityOff>
  </gazebo>
 
  <gazebo reference="TS24">
<material>Gazebo/Grey</material>
    <turnGravityOff>true</turnGravityOff>
  </gazebo>
 
<joint name="TSJ1" type="fixed">
	<parent link="centerplate" />
	<child link="TS1" />
	<origin xyz="0 0 .4" rpy="0 0 0" />
	<axis xyz="1 0 0" /> 
</joint>

<joint name="TSJ2" type="continuous">
	<parent link="TS1" />
	<child link="TS2" />
	<origin xyz="0 0 .052" rpy="0 0 0" />
		<axis xyz="1 0 0" /> 
</joint>

<joint name="TSJ3" type="continuous">
	<parent link="TS2" />
	<child link="TS3" />
	<origin xyz="0 0 .052" rpy="0 0 0" />
		<axis xyz="1 0 0" /> 
</joint>

<joint name="TSJ4" type="continuous">
	<parent link="TS3" />
	<child link="TS4" />
	<origin xyz="0 0 .052" rpy="0 0 0" />
		<axis xyz="1 0 0" /> 
</joint>

<joint name="TSJ5" type="continuous">
	<parent link="TS4" />
	<child link="TS5" />
	<origin xyz="0 0 .052" rpy="0 0 0" />
		<axis xyz="1 0 0" /> 
</joint>

<joint name="TSJ6" type="continuous">
	<parent link="TS5" />
	<child link="TS6" />
	<origin xyz="0 0 .052" rpy="0 0 0" />	
	<axis xyz="1 0 0" /> 
</joint>

<joint name="TSJ7" type="continuous">
	<parent link="TS6" />
	<child link="TS7" />
	<origin xyz="0 0 .052" rpy="0 0 0" />
		<axis xyz="1 0 0" /> 
</joint>

<joint name="TSJ8" type="continuous">
	<parent link="TS7" />
	<child link="TS8" />
	<origin xyz="0 0 .052" rpy="0 0 0" />
		<axis xyz="1 0 0" /> 
</joint>

<joint name="TSJ9" type="continuous">
	<parent link="TS8" />
	<child link="TS9" />
	<origin xyz="0 0 .052" rpy="0 0 0" />
		<axis xyz="1 0 0" /> 
</joint>

<joint name="TSJ10" type="continuous">
	<parent link="TS9" />
	<child link="TS10" />
	<origin xyz="0 0 .052" rpy="0 0 0" />
		<axis xyz="1 0 0" /> 
</joint>

<joint name="TSJ11" type="continuous">
	<parent link="TS10" />
	<child link="TS11" />
	<origin xyz="0 0 .052" rpy="0 0 0" />
		<axis xyz="1 0 0" /> 
</joint>

<joint name="TSJ12" type="continuous">
	<parent link="TS11" />
	<child link="TS12" />
	<origin xyz="0 0 .052" rpy="0 0 0" />
		<axis xyz="1 0 0" /> 
</joint>

<joint name="TSJ13" type="continuous">
	<parent link="TS12" />
	<child link="TS13" />
	<origin xyz="0 0 .052" rpy="0 0 0" />
		<axis xyz="1 0 0" /> 
</joint>

<joint name="TSJ14" type="continuous">
	<parent link="TS13" />
	<child link="TS14" />
	<origin xyz="0 0 .052" rpy="0 0 0" />
		<axis xyz="1 0 0" /> 
</joint>

<joint name="TSJ15" type="continuous">
	<parent link="TS14" />
	<child link="TS15" />
	<origin xyz="0 0 .052" rpy="0 0 0" />
		<axis xyz="1 0 0" /> 
</joint>

<joint name="TSJ16" type="continuous">
	<parent link="TS15" />
	<child link="TS16" />
	<origin xyz="0 0 .052" rpy="0 0 0" />
		<axis xyz="1 0 0" /> 
</joint>

<joint name="TSJ17" type="continuous">
	<parent link="TS16" />
	<child link="TS17" />
	<origin xyz="0 0 .052" rpy="0 0 0" />
		<axis xyz="1 0 0" /> 
</joint>

<joint name="TSJ18" type="continuous">
	<parent link="TS17" />
	<child link="TS18" />
	<origin xyz="0 0 .052" rpy="0 0 0" />
		<axis xyz="1 0 0" /> 
</joint>

<joint name="TSJ19" type="continuous">
	<parent link="TS18" />
	<child link="TS19" />
	<origin xyz="0 0 .052" rpy="0 0 0" />
		<axis xyz="1 0 0" /> 
</joint>

<joint name="TSJ20" type="continuous">
	<parent link="TS19" />
	<child link="TS20" />
	<origin xyz="0 0 .052" rpy="0 0 0" />
		<axis xyz="1 0 0" /> 
</joint>

<joint name="TSJ21" type="continuous">
	<parent link="TS20" />
	<child link="TS21" />
	<origin xyz="0 0 .052" rpy="0 0 0" />
		<axis xyz="1 0 0" /> 
</joint>

<joint name="TSJ22" type="continuous">
	<parent link="TS21" />
	<child link="TS22" />
	<origin xyz="0 0 .052" rpy="0 0 0" />
		<axis xyz="1 0 0" /> 
</joint>

<joint name="TorsoBend" type="continuous">
	<parent link="TS22" />
	<child link="TS23" />
	<origin xyz="0 0 .052" rpy="0 0 0" />
		<axis xyz="1 0 0" /> 
</joint>

<joint name="TSJ23" type="fixed">
	<parent link="TS23" />
	<child link="TS24" />
	<origin xyz="0 0 .052" rpy="0 0 0" />
		<axis xyz="1 0 0" /> 
</joint>

<joint name="TSShoulderJoint" type="fixed">
	<origin xyz="0 -.85 .45" rpy="-.28 0 0"/>
	<axis xyz="1 0 0" /> 
	<parent link="TS24"/>
	<child link="shoulders"/>
</joint>


<!--
-----------------------------Sparky Lower Spine ------------------------------
-->

<link name="LS1">
<inertial>
		<mass value="5"/>
		<inertia ixx="100" ixy="0" ixz="0" iyy="100" iyz="0" izz="100" />
		<origin/>
	</inertial>
	<visual>
	<origin xyz="0 0 0" rpy="0 0 0" />
	<material name="silver" >
		<color rgba=".5 .5 .5 .5" />
	</material>
	<geometry>
		<cylinder radius=".25" length=".098" />
	</geometry>
	</visual>
		    <collision>
      <origin xyz="0 0 0" rpy="0 0 0 " />
      <geometry name="collision_geom">
        <cylinder radius=".25" length=".104" />
      </geometry>
    </collision>
</link>



<link name="LS2">
<inertial>
		<mass value="5"/>
		<inertia ixx="100" ixy="0" ixz="0" iyy="100" iyz="0" izz="100" />
		<origin/>
	</inertial>
	<visual>
	<origin xyz="0 0 0" rpy="0 0 0" />
	<material name="silver" >
	</material>
	<geometry>
		<cylinder radius=".25" length=".098" />
	</geometry>
	</visual>
		    <collision>
      <origin xyz="0 0 0" rpy="0 0 0 " />
      <geometry name="collision_geom">
        <cylinder radius=".25" length=".104" />
      </geometry>
    </collision>
</link>

<link name="LS3">
<inertial>
		<mass value="5"/>
		<inertia ixx="100" ixy="0" ixz="0" iyy="100" iyz="0" izz="100" />
		<origin/>
	</inertial>
	<visual>
	<origin xyz="0 0 0" rpy="0 0 0" />
	<material name="silver" >
	</material>
	<geometry>
		<cylinder radius=".25" length=".098" />
	</geometry>
	</visual>
		    <collision>
      <origin xyz="0 0 0" rpy="0 0 0 " />
      <geometry name="collision_geom">
        <cylinder radius=".25" length=".104" />
      </geometry>
    </collision>
</link>

<link name="LS4">
<inertial>
		<mass value="5"/>
		<inertia ixx="100" ixy="0" ixz="0" iyy="100" iyz="0" izz="100" />
		<origin/>
	</inertial>
	<visual>
	<origin xyz="0 0 0" rpy="0 0 0" />
	<material name="silver" >
	</material>
	<geometry>
		<cylinder radius=".25" length=".098" />
	</geometry>
	</visual>
		    <collision>
      <origin xyz="0 0 0" rpy="0 0 0 " />
      <geometry name="collision_geom">
        <cylinder radius=".25" length=".104" />
      </geometry>
    </collision>
</link>

<link name="LS5">
<inertial>
		<mass value="5"/>
		<inertia ixx="100" ixy="0" ixz="0" iyy="100" iyz="0" izz="100" />
		<origin/>
	</inertial>
	<visual>
	<origin xyz="0 0 0" rpy="0 0 0" />
	<material name="silver" >
	</material>
	<geometry>
		<cylinder radius=".25" length=".098" />
	</geometry>
	</visual>
		    <collision>
      <origin xyz="0 0 0" rpy="0 0 0 " />
      <geometry name="collision_geom">
        <cylinder radius=".25" length=".104" />
      </geometry>
    </collision>
</link>


<link name="LS6">
<inertial>
		<mass value="5"/>
		<inertia ixx="100" ixy="0" ixz="0" iyy="100" iyz="0" izz="100" />
		<origin/>
	</inertial>
	<visual>
	<origin xyz="0 0 0" rpy="0 0 0" />
	<material name="silver" >
	</material>
	<geometry>
		<cylinder radius=".25" length=".098" />
	</geometry>
	</visual>
		    <collision>
      <origin xyz="0 0 0" rpy="0 0 0 " />
      <geometry name="collision_geom">
        <cylinder radius=".25" length=".104" />
      </geometry>
    </collision>
</link>

<link name="LS7">
<inertial>
		<mass value="5"/>
		<inertia ixx="100" ixy="0" ixz="0" iyy="100" iyz="0" izz="100" />
		<origin/>
	</inertial>
	<visual>
	<origin xyz="0 0 0" rpy="0 0 0" />
	<material name="silver" >
	</material>
	<geometry>
		<cylinder radius=".25" length=".098" />
	</geometry>
	</visual>
		    <collision>
      <origin xyz="0 0 0" rpy="0 0 0 " />
      <geometry name="collision_geom">
        <cylinder radius=".25" length=".104" />
      </geometry>
    </collision>
	
</link>

<link name="LS8">
<inertial>
		<mass value="5"/>
		<inertia ixx="100" ixy="0" ixz="0" iyy="100" iyz="0" izz="100" />
		<origin/>
	</inertial>
	<visual>
	<origin xyz="0 0 0" rpy="0 0 0" />
	<material name="silver" >
	</material>
	<geometry>
		<cylinder radius=".25" length=".098" />
	</geometry>
	</visual>
		    <collision>
      <origin xyz="0 0 0" rpy="0 0 0 " />
      <geometry name="collision_geom">
        <cylinder radius=".25" length=".104" />
      </geometry>
    </collision>
	
</link>

<link name="LS9">
<inertial>
		<mass value="5"/>
		<inertia ixx="100" ixy="0" ixz="0" iyy="100" iyz="0" izz="100" />
		<origin/>
	</inertial>
	<visual>
	<origin xyz="0 0 0" rpy="0 0 0" />
	<material name="silver" >
		<color rgba=".5 .5 .5 .5" />
	</material>
	<geometry>
		<cylinder radius=".25" length=".098" />
	</geometry>
	</visual>
		    <collision>
      <origin xyz="0 0 0" rpy="0 0 0 " />
      <geometry name="collision_geom">
        <cylinder radius=".25" length=".104" />
      </geometry>
    </collision>
</link>



<link name="LS10">
<inertial>
		<mass value="5"/>
		<inertia ixx="100" ixy="0" ixz="0" iyy="100" iyz="0" izz="100" />
		<origin/>
	</inertial>
	<visual>
	<origin xyz="0 0 0" rpy="0 0 0" />
	<material name="silver" >
	</material>
	<geometry>
		<cylinder radius=".25" length=".098" />
	</geometry>
	</visual>
		    <collision>
      <origin xyz="0 0 0" rpy="0 0 0 " />
      <geometry name="collision_geom">
        <cylinder radius=".25" length=".104" />
      </geometry>
    </collision>
</link>

<link name="LS11">
<inertial>
		<mass value="5"/>
		<inertia ixx="100" ixy="0" ixz="0" iyy="100" iyz="0" izz="100" />
		<origin/>
	</inertial>
	<visual>
	<origin xyz="0 0 0" rpy="0 0 0" />
	<material name="silver" >
	</material>
	<geometry>
		<cylinder radius=".25" length=".098" />
	</geometry>
	</visual>
		    <collision>
      <origin xyz="0 0 0" rpy="0 0 0 " />
      <geometry name="collision_geom">
        <cylinder radius=".25" length=".104" />
      </geometry>
    </collision>
</link>

<link name="LS12">
<inertial>
		<mass value="5"/>
		<inertia ixx="100" ixy="0" ixz="0" iyy="100" iyz="0" izz="100" />
		<origin/>
	</inertial>
	<visual>
	<origin xyz="0 0 0" rpy="0 0 0" />
	<material name="silver" >
	</material>
	<geometry>
		<cylinder radius=".25" length=".098" />
	</geometry>
	</visual>
		    <collision>
      <origin xyz="0 0 0" rpy="0 0 0 " />
      <geometry name="collision_geom">
        <cylinder radius=".25" length=".104" />
      </geometry>
    </collision>
</link>

<link name="LS13">
<inertial>
		<mass value="5"/>
		<inertia ixx="100" ixy="0" ixz="0" iyy="100" iyz="0" izz="100" />
		<origin/>
	</inertial>
	<visual>
	<origin xyz="0 0 0" rpy="0 0 0" />
	<material name="silver" >
	</material>
	<geometry>
		<cylinder radius=".25" length=".098" />
	</geometry>
	</visual>
		    <collision>
      <origin xyz="0 0 0" rpy="0 0 0 " />
      <geometry name="collision_geom">
        <cylinder radius=".25" length=".104" />
      </geometry>
    </collision>
</link>

<link name="LS14">
<inertial>
		<mass value="5"/>
		<inertia ixx="100" ixy="0" ixz="0" iyy="100" iyz="0" izz="100" />
		<origin/>
	</inertial>
	<visual>
	<origin xyz="0 0 0" rpy="0 0 0" />
	<material name="silver" >
	</material>
	<geometry>
		<cylinder radius=".25" length=".098" />
	</geometry>
	</visual>
		    <collision>
      <origin xyz="0 0 0" rpy="0 0 0 " />
      <geometry name="collision_geom">
        <cylinder radius=".25" length=".104" />
      </geometry>
    </collision>
</link>

<link name="LS15">
<inertial>
		<mass value="5"/>
		<inertia ixx="100" ixy="0" ixz="0" iyy="100" iyz="0" izz="100" />
		<origin/>
	</inertial>
	<visual>
	<origin xyz="0 0 0" rpy="0 0 0" />
	<material name="silver" >
	</material>
	<geometry>
		<cylinder radius=".25" length=".098" />
	</geometry>
	</visual>
		    <collision>
      <origin xyz="0 0 0" rpy="0 0 0 " />
      <geometry name="collision_geom">
        <cylinder radius=".25" length=".104" />
      </geometry>
    </collision>
	
</link>

<link name="LS16">
<inertial>
		<mass value="5"/>
		<inertia ixx="100" ixy="0" ixz="0" iyy="100" iyz="0" izz="100" />
		<origin/>
	</inertial>
	<visual>
	<origin xyz="0 0 0" rpy="0 0 0" />
	<material name="silver" >
	</material>
	<geometry>
		<cylinder radius=".25" length=".098" />
	</geometry>
	</visual>
		    <collision>
      <origin xyz="0 0 0" rpy="0 0 0 " />
      <geometry name="collision_geom">
        <cylinder radius=".25" length=".104" />
      </geometry>
    </collision>
	
</link>
<link name="LS17">
<inertial>
		<mass value="5"/>
		<inertia ixx="100" ixy="0" ixz="0" iyy="100" iyz="0" izz="100" />
		<origin/>
	</inertial>
	<visual>
	<origin xyz="0 0 0" rpy="0 0 0" />
	<material name="silver" >
		<color rgba=".5 .5 .5 .5" />
	</material>
	<geometry>
		<cylinder radius=".25" length=".098" />
	</geometry>
	</visual>
		    <collision>
      <origin xyz="0 0 0" rpy="0 0 0 " />
      <geometry name="collision_geom">
        <cylinder radius=".25" length=".104" />
      </geometry>
    </collision>
</link>



<link name="LS18">
<inertial>
		<mass value="5"/>
		<inertia ixx="100" ixy="0" ixz="0" iyy="100" iyz="0" izz="100" />
		<origin/>
	</inertial>
	<visual>
	<origin xyz="0 0 0" rpy="0 0 0" />
	<material name="silver" >
	</material>
	<geometry>
		<cylinder radius=".25" length=".098" />
	</geometry>
	</visual>
		    <collision>
      <origin xyz="0 0 0" rpy="0 0 0 " />
      <geometry name="collision_geom">
        <cylinder radius=".25" length=".104" />
      </geometry>
    </collision>
</link>

<link name="LS19">
<inertial>
		<mass value="5"/>
		<inertia ixx="100" ixy="0" ixz="0" iyy="100" iyz="0" izz="100" />
		<origin/>
	</inertial>
	<visual>
	<origin xyz="0 0 0" rpy="0 0 0" />
	<material name="silver" >
	</material>
	<geometry>
		<cylinder radius=".25" length=".098" />
	</geometry>
	</visual>
		    <collision>
      <origin xyz="0 0 0" rpy="0 0 0 " />
      <geometry name="collision_geom">
        <cylinder radius=".25" length=".104" />
      </geometry>
    </collision>
</link>

<link name="LS20">
<inertial>
		<mass value="5"/>
		<inertia ixx="100" ixy="0" ixz="0" iyy="100" iyz="0" izz="100" />
		<origin/>
	</inertial>
	<visual>
	<origin xyz="0 0 0" rpy="0 0 0" />
	<material name="silver" >
	</material>
	<geometry>
		<cylinder radius=".25" length=".098" />
	</geometry>
	</visual>
		    <collision>
      <origin xyz="0 0 0" rpy="0 0 0 " />
      <geometry name="collision_geom">
        <cylinder radius=".25" length=".104" />
      </geometry>
    </collision>
</link>

  <gazebo reference="LS1">
<material>Gazebo/Grey</material>
    <turnGravityOff>true</turnGravityOff>
  </gazebo>
 
  <gazebo reference="LS2">
<material>Gazebo/Grey</material>
    <turnGravityOff>true</turnGravityOff>
  </gazebo>
 
  <gazebo reference="LS3">
<material>Gazebo/Grey</material>
    <turnGravityOff>true</turnGravityOff>
  </gazebo>
 
  <gazebo reference="LS4">
<material>Gazebo/Grey</material>
    <turnGravityOff>true</turnGravityOff>
  </gazebo>
 
  <gazebo reference="LS5">
<material>Gazebo/Grey</material>
    <turnGravityOff>true</turnGravityOff>
  </gazebo>
 
  <gazebo reference="LS6">
<material>Gazebo/Grey</material>
    <turnGravityOff>true</turnGravityOff>
  </gazebo>
 
  <gazebo reference="LS7">
<material>Gazebo/Grey</material>
    <turnGravityOff>true</turnGravityOff>
  </gazebo>
 
  <gazebo reference="LS8">
<material>Gazebo/Grey</material>
    <turnGravityOff>true</turnGravityOff>
  </gazebo>
 
  <gazebo reference="LS9">
<material>Gazebo/Grey</material>
    <turnGravityOff>true</turnGravityOff>
  </gazebo>
 
  <gazebo reference="LS10">
<material>Gazebo/Grey</material>
    <turnGravityOff>true</turnGravityOff>
  </gazebo>
 
  <gazebo reference="LS11">
<material>Gazebo/Grey</material>
    <turnGravityOff>true</turnGravityOff>
  </gazebo>
 
  <gazebo reference="LS12">
<material>Gazebo/Grey</material>
    <turnGravityOff>true</turnGravityOff>
  </gazebo>
 
  <gazebo reference="LS13">
<material>Gazebo/Grey</material>
    <turnGravityOff>true</turnGravityOff>
  </gazebo>
 
  <gazebo reference="LS14">
<material>Gazebo/Grey</material>
    <turnGravityOff>true</turnGravityOff>
  </gazebo>
 
  <gazebo reference="LS15">
<material>Gazebo/Grey</material>
    <turnGravityOff>true</turnGravityOff>
  </gazebo>
 
  <gazebo reference="LS16">
<material>Gazebo/Grey</material>
    <turnGravityOff>true</turnGravityOff>
  </gazebo>
 
  <gazebo reference="LS17">
<material>Gazebo/Grey</material>
    <turnGravityOff>true</turnGravityOff>
  </gazebo>
 
  <gazebo reference="LS18">
<material>Gazebo/Grey</material>
    <turnGravityOff>true</turnGravityOff>
  </gazebo>
 
  <gazebo reference="LS19">
<material>Gazebo/Grey</material>
    <turnGravityOff>true</turnGravityOff>
  </gazebo>
 
  <gazebo reference="LS20">
<material>Gazebo/Grey</material>
    <turnGravityOff>true</turnGravityOff>
  </gazebo>
 


<joint name="LSJ1" type="fixed">
	<parent link="hips" />
	<child link="LS1" />
	<origin xyz="0 0 1.3" rpy="0 0 0" />
		<axis xyz="1 0 0" /> 
</joint>

<joint name="LSJ2" type="continuous">
	<parent link="LS1" />
	<child link="LS2" />
	<origin xyz="0 0 .049" rpy="0 0 0" />
		<axis xyz="1 0 0" /> 
</joint>

<joint name="LSJ3" type="continuous">
	<parent link="LS2" />
	<child link="LS3" />
	<origin xyz="0 0 .049" rpy="0 0 0" />
		<axis xyz="1 0 0" /> 
</joint>

<joint name="LSJ4" type="continuous">
	<parent link="LS3" />
	<child link="LS4" />
	<origin xyz="0 0 .049" rpy="0 0 0" />
		<axis xyz="1 0 0" /> 
</joint>

<joint name="LSJ5" type="continuous">
	<parent link="LS4" />
	<child link="LS5" />
	<origin xyz="0 0 .049" rpy="0 0 0" />
		<axis xyz="1 0 0" /> 
</joint>

<joint name="LSJ6" type="continuous">
	<parent link="LS5" />
	<child link="LS6" />
	<origin xyz="0 0 .049" rpy="0 0 0" />
		<axis xyz="1 0 0" /> 
</joint>

<joint name="LSJ7" type="continuous">
	<parent link="LS6" />
	<child link="LS7" />
	<origin xyz="0 0 .049" rpy="0 0 0" />
		<axis xyz="1 0 0" /> 
</joint>

<joint name="LSJ8" type="continuous">
	<parent link="LS7" />
	<child link="LS8" />
	<origin xyz="0 0 .049" rpy="0 0 0" />
		<axis xyz="1 0 0" /> 
</joint>

<joint name="LSJ9" type="continuous">
	<parent link="LS8" />
	<child link="LS9" />
	<origin xyz="0 0 .049" rpy="0 0 0" />
		<axis xyz="1 0 0" /> 
</joint>

<joint name="LSJ10" type="continuous">
	<parent link="LS9" />
	<child link="LS10" />
	<origin xyz="0 0 .049" rpy="0 0 0" />
		<axis xyz="1 0 0" /> 
</joint>

<joint name="LSJ11" type="continuous">
	<parent link="LS10" />
	<child link="LS11" />
	<origin xyz="0 0 .049" rpy="0 0 0" />
		<axis xyz="1 0 0" /> 
</joint>

<joint name="LSJ12" type="continuous">
	<parent link="LS11" />
	<child link="LS12" />
	<origin xyz="0 0 .049" rpy="0 0 0" />
		<axis xyz="1 0 0" /> 
</joint>

<joint name="LSJ13" type="continuous">
	<parent link="LS12" />
	<child link="LS13" />
	<origin xyz="0 0 .049" rpy="0 0 0" />
		<axis xyz="1 0 0" /> 
</joint>

<joint name="LSJ14" type="continuous">
	<parent link="LS13" />
	<child link="LS14" />
	<origin xyz="0 0 .049" rpy="0 0 0" />
		<axis xyz="1 0 0" /> 
</joint>

<joint name="LSJ15" type="continuous">
	<parent link="LS14" />
	<child link="LS15" />
	<origin xyz="0 0 .049" rpy="0 0 0" />
		<axis xyz="1 0 0" /> 
</joint>

<joint name="LSJ16" type="continuous">
	<parent link="LS15" />
	<child link="LS16" />
	<origin xyz="0 0 .049" rpy="0 0 0" />
		<axis xyz="1 0 0" /> 
</joint>

<joint name="LSJ17" type="continuous">
	<parent link="LS16" />
	<child link="LS17" />
	<origin xyz="0 0 .049" rpy="0 0 0" />
		<axis xyz="1 0 0" /> 
</joint>

<joint name="LSJ18" type="continuous">
	<parent link="LS17" />
	<child link="LS18" />
	<origin xyz="0 0 .049" rpy="0 0 0" />
		<axis xyz="1 0 0" /> 
</joint>

<joint name="LSJ19" type="continuous">
	<parent link="LS18" />
	<child link="LS19" />
	<origin xyz="0 0 .049" rpy="0 0 0" />
		<axis xyz="1 0 0" /> 
</joint>

<joint name="LSJ20" type="continuous">
	<parent link="LS19" />
	<child link="LS20" />
	<origin xyz="0 0 .049" rpy="0 0 0" />
		<axis xyz="1 0 0" /> 
</joint>


<joint name="LSJ21" type="fixed">
	<parent link="LS20" />
	<child link="centerplate" />
	<origin xyz="0 0 .42" rpy="0 0 0" />
		<axis xyz="1 0 0" /> 
</joint>


  <!-- mechanism controls -->
  <include filename="./sparky.transmission.xacro" />

  <gazebo>
      <controller:gazebo_ros_time name="gazebo_ros_time" plugin="libgazebo_ros_time.so">
        <alwaysOn>true</alwaysOn>
        <updateRate>1000.0</updateRate>
        <interface:audio name="dummy_gazebo_ros_time_iface_should_not_be_here"/>
      </controller:gazebo_ros_time>

      <!-- SPARKY_ACTARRAY -->
      <controller:gazebo_ros_controller_manager name="gazebo_ros_controller_manager" plugin="libgazebo_ros_controller_manager.so">
        <alwaysOn>true</alwaysOn>
        <updateRate>1000.0</updateRate>

        <interface:audio name="gazebo_ros_controller_manager_dummy_iface" />
      </controller:gazebo_ros_controller_manager>

      <!-- gazebo_ros_p3d for position groundtruth -->
      <controller:gazebo_ros_p3d name="p3d_LtElbow_controller" plugin="libgazebo_ros_p3d.so">
          <alwaysOn>true</alwaysOn>
          <updateRate>1000.0</updateRate>
          <bodyName>LtElbow</bodyName>
          <topicName>LtElbow_pose</topicName>
          <frameName>map</frameName>
          <interface:position name="p3d_LtElbow_position"/>
      </controller:gazebo_ros_p3d>
  </gazebo>
  

</robot>


