<?xml version="1.0" ?>
<!-- =================================================================================== -->
<!-- |    This document was autogenerated by xacro from /home/astclair/workspaces/groovy/stacks/usc-interaction-software/bandit/bandit_urdf/urdf/bandit_defs.urdf.xacro | -->
<!-- |    EDITING THIS FILE BY HAND IS NOT RECOMMENDED                                 | -->
<!-- =================================================================================== -->
<robot name="bandit" xmlns:xacro="http://ros.org/wiki/xacro">
  <!-- Import Rviz colors -->
  <material name="Red">
    <color rgba="0.8 0.0 0.0 1.0"/>
  </material>
  <material name="Blue">
    <color rgba="0.0 0.0 0.8 1.0"/>
  </material>
  <material name="Green">
    <color rgba="0.0 0.8 0.0 1.0"/>
  </material>
  <material name="Yellow">
    <color rgba="0.75 0.75 0.0 1.0"/>
  </material>
  <material name="Black">
    <color rgba="0 0 0 1.0"/>
  </material>
  <material name="White">
    <color rgba="1.0 1.0 1.0 1.0"/>
  </material>
  <material name="Head">
    <color rgba="0.5 0.5 0.5 1.0"/>
  </material>
  <material name="Eyebrows">
    <color rgba="0.35 0.35 0.35 1.0"/>
  </material>
  <material name="Pupil">
    <color rgba="0 0 0 1"/>
  </material>
  <material name="Lips">
    <color rgba="0.737 0.118 0.193 1.0"/>
  </material>
  <material name="Neck">
    <color rgba="0.5 0.5 0.5 1.0"/>
  </material>
  <material name="Torso">
    <color rgba="0.3 0.3 0.3 1.0"/>
  </material>
  <material name="Arms">
    <color rgba="0.5 0.5 0.5 1.0"/>
  </material>
  <material name="Wrist">
    <color rgba="0.5 0.5 0.5 1.0"/>
  </material>
  <material name="Hands">
    <color rgba="0.5 0.5 0.5 1.0"/>
  </material>
  <material name="SweaterRed">
    <color rgba="0.45 0.0 0.0 1.0"/>
  </material>
  <joint name="pupil_left_joint" type="fixed">
    <origin rpy="0 0 0" xyz="0.0012 -0.0048 -0.032"/>
    <parent link="eye_left_camera_link"/>
    <child link="pupil_left_link"/>
  </joint>
  <link name="pupil_left_link">
    <inertial>
      <mass value="0.01"/>
      <origin xyz="0 0 0"/>
      <inertia ixx="1" ixy="0" ixz="0" iyy="1" iyz="0" izz="1"/>
    </inertial>
    <visual name="pupil_visual">
      <origin rpy="0 0 0" xyz="0 0 0"/>
      <geometry name="pupil_left_geom">
        <mesh filename="package://bandit_urdf/meshes/bandit_mesh/middle_eye.stl"/>
      </geometry>
      <material name="Pupil">
        <color rgba="0 0 0 1"/>
      </material>
    </visual>
    <collision>
      <origin rpy="0 0 0" xyz="0 0 0"/>
      <geometry>
        <box size="0 0 0"/>
      </geometry>
    </collision>
  </link>
  <joint name="pupil_right_joint" type="fixed">
    <origin rpy="0 0 0" xyz="0.0012 -0.0046 -0.032"/>
    <parent link="eye_right_camera_link"/>
    <child link="pupil_right_link"/>
  </joint>
  <link name="pupil_right_link">
    <inertial>
      <mass value="0.01"/>
      <origin xyz="0 0 0"/>
      <inertia ixx="1" ixy="0" ixz="0" iyy="1" iyz="0" izz="1"/>
    </inertial>
    <visual name="pupil_visual">
      <origin rpy="0 0 0" xyz="0 0 0"/>
      <geometry name="pupil_left_geom">
        <mesh filename="package://bandit_urdf/meshes/bandit_mesh/middle_eye.stl"/>
      </geometry>
      <material name="Pupil">
        <color rgba="0 0 0 1"/>
      </material>
    </visual>
    <collision>
      <origin rpy="0 0 0" xyz="0 0 0"/>
      <geometry>
        <box size="0 0 0"/>
      </geometry>
    </collision>
  </link>
  <!-- Import all Gazebo-customization elements, including Gazebo colors -->
  <gazebo reference="torso_link">
    <material>Gazebo/Grey</material>
  </gazebo>
  <gazebo reference="stop_link">
    <material>Gazebo/Red</material>
  </gazebo>
  <gazebo reference="head_pan_link">
    <material>Gazebo/Red</material>
  </gazebo>
  <gazebo reference="head_tilt_link">
    <material>Gazebo/Red</material>
  </gazebo>
  <transmission name="head_pan_trans" type="SimpleTransmission">
    <actuator name="$head_pan_motor"/>
    <joint name="head_pan_joint"/>
    <mechanicalReduction>1.0</mechanicalReduction>
  </transmission>
  <transmission name="head_tilt_trans" type="SimpleTransmission">
    <actuator name="$head_tilt_motor"/>
    <joint name="head_tilt_joint"/>
    <mechanicalReduction>1.0</mechanicalReduction>
  </transmission>
  <!-- Used for fixing robot to Gazebo 'base_link' -->
  <link name="world"/>
  <joint name="fixed" type="fixed">
    <parent link="world"/>
    <child link="torso_link"/>
  </joint>
  <link name="torso_link">
    <inertial>
      <mass value="0.01"/>
      <origin xyz="0 0 0"/>
      <inertia ixx="1" ixy="0" ixz="0" iyy="1" iyz="0" izz="1"/>
    </inertial>
    <visual name="torso_visual">
      <material name="Torso"/>
      <origin rpy="1.57079632679 0 1.57079632679" xyz="0 0 0.0"/>
      <geometry name="torso_geom">
        <mesh filename="package://bandit_urdf/meshes/bandit_mesh/body_small.stl"/>
      </geometry>
    </visual>
    <collision>
      <origin rpy="0 0 0" xyz="0 0 -0.067"/>
      <geometry>
        <box size="0.152 0.228 0.282"/>
      </geometry>
    </collision>
  </link>
  <link name="stop_link">
    <inertial>
      <mass value="0.01"/>
      <origin xyz="0 0 0"/>
      <inertia ixx="1" ixy="0" ixz="0" iyy="1" iyz="0" izz="1"/>
    </inertial>
    <visual name="base_visual">
      <origin rpy="0 1.57079632679 3.14159265359" xyz="0 0 0"/>
      <geometry name="pioneer_geom">
        <mesh filename="package://bandit_urdf/meshes/bandit_mesh/stop_switch_small.STL"/>
      </geometry>
      <material name="Red"/>
    </visual>
    <collision>
      <origin rpy="0 0 0" xyz="0 0 0"/>
      <geometry>
        <box size="0 0 0"/>
      </geometry>
    </collision>
  </link>
  <joint name="stop_joint" type="fixed">
    <origin rpy="0 0 0" xyz="-0.08 0 -0.04"/>
    <parent link="torso_link"/>
    <child link="stop_link"/>
  </joint>
  <joint name="head_pan_joint" type="revolute">
    <axis xyz="0 0 1"/>
    <origin xyz="0 0 0.1105"/>
    <parent link="torso_link"/>
    <child link="head_pan_link"/>
    <limit effort="2.645" lower="-1.57079633" upper="1.57079633" velocity="6"/>
    <safety_controller k_position="100" k_velocity="1.5" soft_lower_limit="-1.42079633" soft_upper_limit="1.42079633"/>
    <calibration reference_position="0.0"/>
    <dynamics damping="1.0"/>
  </joint>
  <link name="head_pan_link">
    <inertial>
      <origin rpy="183.928 0 -90" xyz="-0.05 0 -0.101"/>
      <mass value="0.01"/>
      <inertia ixx="0.00482611007" ixy="-0.000144683999" ixz="0.000110076136" iyy="0.005218991412" iyz="-0.000314239509" izz="0.008618784925"/>
    </inertial>
    <visual name="head_pan_visual">
      <origin rpy="1.5696 0 -1.5696" xyz="0 0 0"/>
      <geometry name="head_pan_visual_geom">
        <mesh filename="package://bandit_urdf/meshes/bandit_mesh/neck_smallest.stl"/>
      </geometry>
      <material name="Neck"/>
    </visual>
    <collision name="head_pan_collision">
      <origin rpy="1.5696 0 1.5696" xyz="0 0 0"/>
      <geometry name="head_pan_visual_geom">
        <box size="0 0 0"/>
      </geometry>
    </collision>
  </link>
  <joint name="head_tilt_joint" type="revolute">
    <axis xyz="0 -1 0.0375"/>
    <limit effort="2.645" lower="-0.261799388" upper="0.261799388" velocity="6"/>
    <safety_controller k_position="100" k_velocity="1.5" soft_lower_limit="-1.42079633" soft_upper_limit="1.42079633"/>
    <calibration reference_position="0.0"/>
    <dynamics damping="1.0"/>
    <origin rpy="0 0 0" xyz="0 0 0"/>
    <parent link="head_pan_link"/>
    <child link="head_tilt_link"/>
  </joint>
  <link name="head_tilt_link">
    <inertial>
      <mass value="0.01"/>
      <origin rpy="1.5696 0 1.5696" xyz="0 0 0"/>
      <inertia ixx="0.00482611007" ixy="-0.000144683999" ixz="0.000110076136" iyy="0.005218991412" iyz="-0.000314239509" izz="0.008618784925"/>
    </inertial>
    <visual name="head_tilt_visual">
      <origin rpy="1.5696 0 1.5696" xyz="-.02 0 .01"/>
      <geometry name="head_tilt_visual_geom">
        <mesh filename="package://bandit_urdf/meshes/bandit_mesh/head_small.stl"/>
      </geometry>
      <material name="Head"/>
    </visual>
    <collision name="head_tilt_collision">
      <origin rpy="0 0 0 " xyz="0.008 0 0.055"/>
      <geometry name="head_tilt_visual_geom">
        <box size="0.147 0.156 0.16"/>
      </geometry>
    </collision>
  </link>
  <joint name="mouth_top_joint" type="revolute">
    <origin rpy="0 0 0" xyz="0.07 0 -0.01"/>
    <axis xyz="0 -1 0"/>
    <limit effort="2.645" lower="-0.261799388" upper="0.261799388" velocity="6"/>
    <safety_controller k_position="100" k_velocity="1.5" soft_lower_limit="-1.42079633" soft_upper_limit="1.42079633"/>
    <calibration reference_position="0.0"/>
    <dynamics damping="1.0"/>
    <origin rpy="0 0 0" xyz="0 0 0"/>
    <parent link="head_tilt_link"/>
    <child link="mouth_top_link"/>
  </joint>
  <link name="mouth_top_link">
    <inertial>
      <mass value="0.01"/>
      <origin rpy="0 0 1.5696" xyz="0 0 0"/>
      <inertia ixx="0.00482611007" ixy="-0.000144683999" ixz="0.000110076136" iyy="0.005218991412" iyz="-0.000314239509" izz="0.008618784925"/>
    </inertial>
    <visual name="mouth_top_visual">
      <origin rpy="0 0 -1.5696" xyz="0 0 .002"/>
      <geometry name="mouth_top_visual_geom">
        <mesh filename="package://bandit_urdf/meshes/bandit_mesh/top_lip_small.STL"/>
      </geometry>
      <material name="Lips"/>
    </visual>
    <collision name="mouth_top_collision">
      <origin rpy="0 0 0 " xyz="0 0 0"/>
      <geometry name="mouth_top_visual_geom">
        <box size="0 0 0"/>
      </geometry>
    </collision>
  </link>
  <joint name="mouth_bottom_joint" type="revolute">
    <origin rpy="0 0 0" xyz="0.07 0 -0.01"/>
    <axis xyz="0 -1 0"/>
    <limit effort="2.645" lower="-0.261799388" upper="0.261799388" velocity="6"/>
    <safety_controller k_position="100" k_velocity="1.5" soft_lower_limit="-1.42079633" soft_upper_limit="1.42079633"/>
    <calibration reference_position="0.0"/>
    <dynamics damping="1.0"/>
    <origin rpy="0 0 0" xyz="0 0 0"/>
    <parent link="head_tilt_link"/>
    <child link="mouth_bottom_link"/>
  </joint>
  <link name="mouth_bottom_link">
    <inertial>
      <mass value="0.01"/>
      <origin rpy="1.5696 0 1.5696" xyz="0 0 0"/>
      <inertia ixx="0.00482611007" ixy="-0.000144683999" ixz="0.000110076136" iyy="0.005218991412" iyz="-0.000314239509" izz="0.008618784925"/>
    </inertial>
    <visual name="mouth_bottom_visual">
      <origin rpy="0 0 -1.5696" xyz="0 0 -0.002"/>
      <geometry name="mouth_bottom_visual_geom">
        <mesh filename="package://bandit_urdf/meshes/bandit_mesh/bottom_lip_small.STL"/>
      </geometry>
      <material name="Lips"/>
    </visual>
    <collision name="mouth_bottom_collision">
      <origin rpy="0 0 0 " xyz="0 0 0"/>
      <geometry name="mouth_bottom_visual_geom">
        <box size="0 0 0"/>
      </geometry>
    </collision>
  </link>
  <joint name="eye_right_camera_joint" type="fixed">
    <origin rpy="-1.57079632679 -0.3 -1.57079632679" xyz="0.05 -0.0320 .060"/>
    <parent link="head_tilt_link"/>
    <child link="eye_right_camera_link"/>
  </joint>
  <link name="eye_right_camera_link">
    <inertial>
      <mass value="0.01"/>
      <origin rpy="1.5696 0 1.5696" xyz="0 0 0"/>
      <inertia ixx="0.00482611007" ixy="-0.000144683999" ixz="0.000110076136" iyy="0.005218991412" iyz="-0.000314239509" izz="0.008618784925"/>
    </inertial>
    <visual name="eye_right_camera_visual">
      <origin rpy="1.5696 0 -1.5696" xyz="0.035 0 0"/>
      <geometry name="eye_right_camera_visual_geom">
        <mesh filename="package://bandit_urdf/meshes/bandit_mesh/camera_board.stl"/>
      </geometry>
      <material name="texture">
        <texture filename="package://bandit_urdf/meshes/bandit_mesh/gradients/reflect1.jpg"/>
      </material>
    </visual>
    <collision name="eye_right_camera_collision">
      <origin rpy="0 0 0 " xyz="0 0 0"/>
      <geometry name="eye_right_camera_visual_geom">
        <box size="0 0 0"/>
      </geometry>
    </collision>
  </link>
  <joint name="eye_left_camera_joint" type="fixed">
    <origin rpy="-1.57079632679 0 -1.57079632679" xyz="0.05 0.0320 .060"/>
    <parent link="head_tilt_link"/>
    <child link="eye_left_camera_link"/>
  </joint>
  <link name="eye_left_camera_link">
    <inertial>
      <mass value="0.01"/>
      <origin rpy="1.5696 0 1.5696" xyz="0 0 0"/>
      <inertia ixx="0.00482611007" ixy="-0.000144683999" ixz="0.000110076136" iyy="0.005218991412" iyz="-0.000314239509" izz="0.008618784925"/>
    </inertial>
    <visual name="eye_left_camera_visual">
      <origin rpy="1.5696 0 -1.5696" xyz="0.035 0 0"/>
      <geometry name="eye_left_camera_visual_geom">
        <mesh filename="package://bandit_urdf/meshes/bandit_mesh/camera_board.stl"/>
      </geometry>
      <material name="texture">
        <texture filename="package://bandit_urdf/meshes/bandit_mesh/gradients/reflect1.jpg"/>
      </material>
    </visual>
    <collision name="eye_left_camera_collision">
      <origin rpy="0 0 0 " xyz="0 0 0"/>
      <geometry name="eye_left_camera_visual_geom">
        <box size="0 0 0"/>
      </geometry>
    </collision>
  </link>
  <joint name="head_left_brow_joint" type="revolute">
    <axis xyz="0 1 0"/>
    <limit effort="2.645" lower="-0.261799388" upper="0.261799388" velocity="6"/>
    <safety_controller k_position="100" k_velocity="1.5" soft_lower_limit="-1.42079633" soft_upper_limit="1.42079633"/>
    <calibration reference_position="0.0"/>
    <dynamics damping="1.0"/>
    <origin rpy="-1.57079632679 -1.57079632679 0" xyz="0.06 0.0470 .085"/>
    <parent link="head_tilt_link"/>
    <child link="head_left_brow_link"/>
  </joint>
  <link name="head_left_brow_link">
    <inertial>
      <mass value="0.01"/>
      <origin rpy="1.5696 0 1.5696" xyz="0 0 0"/>
      <inertia ixx="0.00482611007" ixy="-0.000144683999" ixz="0.000110076136" iyy="0.005218991412" iyz="-0.000314239509" izz="0.008618784925"/>
    </inertial>
    <visual name="head_left_brow_visual">
      <origin rpy="0 0 -1.5696" xyz="0 0 0"/>
      <geometry name="head_left_brow_visual_geom">
        <mesh filename="package://bandit_urdf/meshes/bandit_mesh/eyebrow_left_small.stl"/>
      </geometry>
      <material name="Eyebrows"/>
    </visual>
    <collision name="head_left_brow_collision">
      <origin rpy="0 0 0 " xyz="0 0 0"/>
      <geometry name="head_left_brow_visual_geom">
        <box size="0 0 0"/>
      </geometry>
    </collision>
  </link>
  <joint name="head_right_brow_joint" type="revolute">
    <axis xyz="0 -1 0"/>
    <limit effort="2.645" lower="-0.261799388" upper="0.261799388" velocity="6"/>
    <safety_controller k_position="100" k_velocity="1.5" soft_lower_limit="-1.42079633" soft_upper_limit="1.42079633"/>
    <calibration reference_position="0.0"/>
    <dynamics damping="1.0"/>
    <origin rpy="-1.57079632679 -1.57079632679 0" xyz="0.06 -0.0470 .085"/>
    <parent link="head_tilt_link"/>
    <child link="head_right_brow_link"/>
  </joint>
  <link name="head_right_brow_link">
    <inertial>
      <mass value="0.01"/>
      <origin rpy="1.5696 0 1.5696" xyz="0 0 0"/>
      <inertia ixx="0.00482611007" ixy="-0.000144683999" ixz="0.000110076136" iyy="0.005218991412" iyz="-0.000314239509" izz="0.008618784925"/>
    </inertial>
    <visual name="head_right_brow_visual">
      <origin rpy="0 0 -1.5696" xyz="0 0 0"/>
      <geometry name="head_right_brow_visual_geom">
        <mesh filename="package://bandit_urdf/meshes/bandit_mesh/eyebrow_right_small.stl"/>
      </geometry>
      <material name="Eyebrows"/>
    </visual>
    <collision name="head_right_brow_collision">
      <origin rpy="0 0 0 " xyz="0 0 0"/>
      <geometry name="head_right_brow_visual_geom">
        <box size="0 0 0"/>
      </geometry>
    </collision>
  </link>
  <joint name="left_torso_shoulder_mounting_joint" type="revolute">
    <axis xyz="0 -1 0"/>
    <origin rpy="0 0 0" xyz="0 0.16 0"/>
    <parent link="torso_link"/>
    <child link="left_shoulder_mounting_link"/>
    <limit effort="30" lower="-3.14159265359" upper="3.14159265359" velocity="6"/>
    <dynamics damping="1.0"/>
    <calibration reference_position="0.0"/>
    <safety_controller k_position="100" k_velocity="10" soft_lower_limit="-3.14159265359" soft_upper_limit="3.14159265359"/>
  </joint>
  <link name="left_shoulder_mounting_link">
    <inertial>
      <origin rpy="3.14159265359 0 0" xyz="-0.035 0.131 0.168"/>
      <mass value="0.01"/>
      <inertia ixx="0.866179142480" ixy="-0.06086507933" ixz="-0.12118061183" iyy="0.87421714893" iyz="-0.05886609911" izz="0.27353821674"/>
    </inertial>
    <visual name="left_shoulder_mounting_link_visual">
      <origin rpy="1.5696 0 1.5696" xyz="0 0 0"/>
      <geometry name="left_shoulder_mounting_link_geom">
        <mesh filename="package://bandit_urdf/meshes/bandit_mesh/shoulder_cover_left_small.stl"/>
      </geometry>
      <material name="Arms"/>
    </visual>
    <collision name="left_shoulder_mounting_link_collision">
      <origin rpy="1.5696 0 1.5696" xyz="0 0 -0.05"/>
      <geometry name="left_shoulder_mounting_link_geom">
        <box size="0.105 0.175 0.081"/>
      </geometry>
    </collision>
  </link>
  <joint name="left_shoulder_mounting_shoulder_joint" type="revolute">
    <origin xyz="0 0.0 0"/>
    <axis xyz="1 0 0"/>
    <parent link="left_shoulder_mounting_link"/>
    <child link="left_shoulder_link"/>
    <limit effort="30" lower="-0.34906585" upper="3.14159265359" velocity="6"/>
    <dynamics damping="1.0"/>
    <calibration reference_position="0.0"/>
    <safety_controller k_position="100" k_velocity="10" soft_lower_limit="-0.34906585" soft_upper_limit="3.14159265359"/>
  </joint>
  <link name="left_shoulder_link">
    <inertial>
      <origin rpy="0 3.1392 0" xyz="-0.030 -0. -0"/>
      <mass value="0.01"/>
      <inertia ixx="0.866179142480" ixy="-0.06086507933" ixz="-0.12118061183" iyy="0.87421714893" iyz="-0.05886609911" izz="0.27353821674"/>
    </inertial>
    <visual name="left_shoulder_link_visual">
      <origin rpy="0 1.57079632679 0" xyz="0 -0.0 0"/>
      <geometry name="left_shoulder_link_geom">
        <mesh filename="package://bandit_urdf/meshes/bandit_mesh/bicep_cover_left_small.stl"/>
      </geometry>
      <material name="Arms"/>
    </visual>
    <collision name="left_shoulder_link_collision">
      <origin rpy="0 0 0" xyz="0 0 -0.04"/>
      <geometry name="left_shoulder_link_geom">
        <box size="0 0 0"/>
      </geometry>
    </collision>
  </link>
  <joint name="left_shoulder_bicep_joint" type="revolute">
    <origin xyz="0 0 -0.161"/>
    <axis xyz="0 0 1"/>
    <parent link="left_shoulder_link"/>
    <child link="left_bicep_link"/>
    <limit effort="30" lower="-1.57079633" upper="1.57079633" velocity="6"/>
    <dynamics damping="1.0"/>
    <calibration reference_position="0.0"/>
    <safety_controller k_position="100" k_velocity="10" soft_lower_limit="-1.57079633" soft_upper_limit="1.57079633"/>
  </joint>
  <link name="left_bicep_link">
    <inertial>
      <origin rpy="0 0 1.5696" xyz="-0.0 0.0 -0.288"/>
      <mass value="0.01"/>
      <inertia ixx="0.866179142480" ixy="-0.06086507933" ixz="-0.12118061183" iyy="0.87421714893" iyz="-0.05886609911" izz="0.27353821674"/>
    </inertial>
    <visual name="left_bicep_link_visual">
      <origin rpy="0 -1.57079632679 1.57079632679" xyz="0 0 0.0"/>
      <geometry name="left_bicep_link_geom">
        <mesh filename="package://bandit_urdf/meshes/bandit_mesh/elbow_cover_left_small.stl"/>
      </geometry>
      <material name="Arms"/>
    </visual>
    <collision name="left_bicep_link_collision">
      <origin rpy="0 0 0" xyz="0 0 0"/>
      <geometry name="left_bicep_link_geom">
        <box size="0 0 0"/>
      </geometry>
    </collision>
  </link>
  <joint name="left_bicep_forearm_joint" type="revolute">
    <origin xyz="0 0 0"/>
    <axis xyz="0 -1.0 0"/>
    <parent link="left_bicep_link"/>
    <child link="left_forearm_link"/>
    <limit effort="30" lower="0.0" upper="1.91986218" velocity="6"/>
    <dynamics damping="1.0"/>
    <calibration reference_position="0.0"/>
    <safety_controller k_position="100" k_velocity="10" soft_lower_limit="0.0" soft_upper_limit="1.91986218"/>
  </joint>
  <link name="left_forearm_link">
    <inertial>
      <origin rpy="0 3.1392 3.1392" xyz="-0.028 0.163 -0.372"/>
      <mass value="0.01"/>
      <inertia ixx="0.866179142480" ixy="-0.06086507933" ixz="-0.12118061183" iyy="0.87421714893" iyz="-0.05886609911" izz="0.27353821674"/>
    </inertial>
    <visual name="left_forearm_link_visual">
      <origin rpy="0 1.57079632679 1.57079632679" xyz="0 0 0"/>
      <geometry name="left_forearm_link_geom">
        <mesh filename="package://bandit_urdf/meshes/bandit_mesh/forearm_cover_left_small.stl"/>
      </geometry>
      <material name="Arms"/>
    </visual>
    <collision name="left_forearm_link_collision">
      <origin rpy="0 0 0" xyz="0 0 -0.075"/>
      <geometry name="left_forearm_link_geom">
        <box size="0 0 0"/>
      </geometry>
    </collision>
  </link>
  <joint name="left_forearm_wrist_joint" type="revolute">
    <origin rpy="0 0 -1.57079632679" xyz="0 0 -0.145"/>
    <axis xyz="0 0 1"/>
    <parent link="left_forearm_link"/>
    <child link="left_wrist_link"/>
    <limit effort="30" lower="-1.57079632679" upper="1.57079632679" velocity="6"/>
    <dynamics damping="1.0"/>
    <calibration reference_position="0.0"/>
    <safety_controller k_position="100" k_velocity="10" soft_lower_limit="-1.57079632679" soft_upper_limit="1.57079632679"/>
  </joint>
  <link name="left_wrist_link">
    <inertial>
      <origin rpy="0 0 0" xyz="-0.026 0.163 -0.434"/>
      <mass value="0.01"/>
      <inertia ixx="0.866179142480" ixy="-0.06086507933" ixz="-0.12118061183" iyy="0.87421714893" iyz="-0.05886609911" izz="0.27353821674"/>
    </inertial>
    <visual name="left_wrist_link_visual">
      <origin rpy="1.57079632679 0 1.57079632679" xyz="0 0 -0.01"/>
      <geometry name="left_wrist_link_geom">
        <mesh filename="package://bandit_urdf/meshes/bandit_mesh/wrist_cover_left_small.stl"/>
      </geometry>
      <material name="Wrist"/>
    </visual>
    <collision name="">
      <origin rpy="0 0 0" xyz="0 0 -0.01"/>
      <geometry name="left_wrist_link_geom">
        <box size="0 0 0"/>
      </geometry>
    </collision>
  </link>
  <joint name="left_wrist_hand_joint" type="revolute">
    <origin xyz="0 0 -0.01"/>
    <axis xyz="0 -1 0"/>
    <parent link="left_wrist_link"/>
    <child link="left_hand_link"/>
    <limit effort="30" lower="-1.57079632679" upper="1.57079632679" velocity="6"/>
    <dynamics damping="1.0"/>
    <calibration reference_position="0.0"/>
    <safety_controller k_position="100" k_velocity="10" soft_lower_limit="-1.57079632679" soft_upper_limit="1.57079632679"/>
  </joint>
  <link name="left_hand_link">
    <inertial>
      <origin rpy="0.99408 0 1.5696" xyz="-0.015 0.163 -0.486"/>
      <mass value="0.01"/>
      <inertia ixx="0.866179142480" ixy="-0.06086507933" ixz="-0.12118061183" iyy="0.87421714893" iyz="-0.05886609911" izz="0.27353821674"/>
    </inertial>
    <visual name="left_hand_link_visual">
      <origin rpy="1.57079632679 0 0" xyz="0 0 -.00"/>
      <geometry name="left_hand_link_geom">
        <mesh filename="package://bandit_urdf/meshes/bandit_mesh/left_hand_small.stl"/>
      </geometry>
      <material name="Hands"/>
    </visual>
    <collision name="left_hand_link_collision">
      <origin rpy="0 0 0" xyz="-0.05 0 -0.06"/>
      <geometry name="left_hand_link_geom">
        <box size="0.03 0.06 0.080"/>
      </geometry>
    </collision>
  </link>
  <joint name="left_hand_thumb_joint" type="revolute">
    <origin xyz="0.014 0 -.033"/>
    <axis xyz="0 1 0"/>
    <parent link="left_hand_link"/>
    <child link="left_thumb_link"/>
    <limit effort="30" lower="-0.714601836603" upper="0" velocity="6"/>
    <dynamics damping="1.0"/>
    <calibration reference_position="0.0"/>
    <safety_controller k_position="100" k_velocity="10" soft_lower_limit="-0.564601836603" soft_upper_limit="-0.15"/>
  </joint>
  <link name="left_thumb_link">
    <inertial>
      <origin rpy="1.5696 0 1.5696" xyz="0.037 0.163 -0.484"/>
      <mass value="0.01"/>
      <inertia ixx="0.866179142480" ixy="-0.06086507933" ixz="-0.12118061183" iyy="0.87421714893" iyz="-0.05886609911" izz="0.27353821674"/>
    </inertial>
    <visual name="left_thumb_link_visual">
      <origin rpy="1.57079632679 -1.57079632679 0" xyz="0 0 0"/>
      <geometry name="left_thumb_link_geom">
        <mesh filename="package://bandit_urdf/meshes/bandit_mesh/left_thumb_small.stl"/>
      </geometry>
      <material name="Hands"/>
    </visual>
    <collision name="left_thumb_link_collision">
      <origin rpy="0 0 0" xyz="0 0 -.015"/>
      <geometry name="left_thumb_link_geom">
        <box size="0.030 0.025 0.06"/>
      </geometry>
    </collision>
  </link>
  <joint name="right_torso_shoulder_mounting_joint" type="revolute">
    <axis xyz="0 -1 0"/>
    <origin rpy="0 0 0" xyz="0 -0.16 0"/>
    <parent link="torso_link"/>
    <child link="right_shoulder_mounting_link"/>
    <limit effort="30" lower="-3.14159265359" upper="3.14159265359" velocity="6"/>
    <dynamics damping="1.0"/>
    <calibration reference_position="0.0"/>
    <safety_controller k_position="100" k_velocity="10" soft_lower_limit="-3.14159265359" soft_upper_limit="3.14159265359"/>
  </joint>
  <link name="right_shoulder_mounting_link">
    <inertial>
      <origin rpy="3.14159265359 0 0" xyz="-0.035 0.131 -0.168"/>
      <mass value="0.01"/>
      <inertia ixx="0.866179142480" ixy="-0.06086507933" ixz="-0.12118061183" iyy="0.87421714893" iyz="-0.05886609911" izz="0.27353821674"/>
    </inertial>
    <visual name="right_shoulder_mounting_link_visual">
      <origin rpy="1.5696 0 1.5696" xyz="0 0 0"/>
      <geometry name="right_shoulder_mounting_link_geom">
        <mesh filename="package://bandit_urdf/meshes/bandit_mesh/shoulder_cover_right_small.stl"/>
      </geometry>
      <material name="Arms"/>
    </visual>
    <collision name="right_shoulder_mounting_link_collision">
      <origin rpy="1.5696 0 1.5696" xyz="0 0 -0.05"/>
      <geometry name="right_shoulder_mounting_link_geom">
        <box size="0.105 0.175 0.081"/>
      </geometry>
    </collision>
  </link>
  <joint name="right_shoulder_mounting_shoulder_joint" type="revolute">
    <origin xyz="0 -0.0 0"/>
    <axis xyz="-1 0 0"/>
    <parent link="right_shoulder_mounting_link"/>
    <child link="right_shoulder_link"/>
    <limit effort="30" lower="-0.34906585" upper="3.14159265359" velocity="6"/>
    <dynamics damping="1.0"/>
    <calibration reference_position="0.0"/>
    <safety_controller k_position="100" k_velocity="10" soft_lower_limit="-0.34906585" soft_upper_limit="3.14159265359"/>
  </joint>
  <link name="right_shoulder_link">
    <inertial>
      <origin rpy="0 3.1392 0" xyz="-0.030 -0. -0"/>
      <mass value="0.01"/>
      <inertia ixx="0.866179142480" ixy="-0.06086507933" ixz="-0.12118061183" iyy="0.87421714893" iyz="-0.05886609911" izz="0.27353821674"/>
    </inertial>
    <visual name="right_shoulder_link_visual">
      <origin rpy="0 1.57079632679 0" xyz="0 0.0 0"/>
      <geometry name="right_shoulder_link_geom">
        <mesh filename="package://bandit_urdf/meshes/bandit_mesh/bicep_cover_right_small.stl"/>
      </geometry>
      <material name="Arms"/>
    </visual>
    <collision name="right_shoulder_link_collision">
      <origin rpy="0 0 0" xyz="0 0 -0.04"/>
      <geometry name="right_shoulder_link_geom">
        <box size="0 0 0"/>
      </geometry>
    </collision>
  </link>
  <joint name="right_shoulder_bicep_joint" type="revolute">
    <origin xyz="0 0 -0.161"/>
    <axis xyz="0 0 -1"/>
    <parent link="right_shoulder_link"/>
    <child link="right_bicep_link"/>
    <limit effort="30" lower="-1.57079633" upper="1.57079633" velocity="6"/>
    <dynamics damping="1.0"/>
    <calibration reference_position="0.0"/>
    <safety_controller k_position="100" k_velocity="10" soft_lower_limit="-1.57079633" soft_upper_limit="1.57079633"/>
  </joint>
  <link name="right_bicep_link">
    <inertial>
      <origin rpy="0 0 1.5696" xyz="-0.0 0.0 -0.288"/>
      <mass value="0.01"/>
      <inertia ixx="0.866179142480" ixy="-0.06086507933" ixz="-0.12118061183" iyy="0.87421714893" iyz="-0.05886609911" izz="0.27353821674"/>
    </inertial>
    <visual name="right_bicep_link_visual">
      <origin rpy="0 -1.57079632679 1.57079632679" xyz="0 0 0.0"/>
      <geometry name="right_bicep_link_geom">
        <mesh filename="package://bandit_urdf/meshes/bandit_mesh/elbow_cover_right_small.stl"/>
      </geometry>
      <material name="Arms"/>
    </visual>
    <collision name="right_bicep_link_collision">
      <origin rpy="0 0 0" xyz="0 0 0"/>
      <geometry name="right_bicep_link_geom">
        <box size="0 0 0"/>
      </geometry>
    </collision>
  </link>
  <joint name="right_bicep_forearm_joint" type="revolute">
    <origin xyz="0 0 0"/>
    <axis xyz="0 -1.0 0"/>
    <parent link="right_bicep_link"/>
    <child link="right_forearm_link"/>
    <limit effort="30" lower="0.0" upper="1.91986218" velocity="6"/>
    <dynamics damping="1.0"/>
    <calibration reference_position="0.0"/>
    <safety_controller k_position="100" k_velocity="10" soft_lower_limit="0.0" soft_upper_limit="1.91986218"/>
  </joint>
  <link name="right_forearm_link">
    <inertial>
      <origin rpy="0 3.1392 3.1392" xyz="-0.028 0.163 -0.372"/>
      <mass value="0.01"/>
      <inertia ixx="0.866179142480" ixy="-0.06086507933" ixz="-0.12118061183" iyy="0.87421714893" iyz="-0.05886609911" izz="0.27353821674"/>
    </inertial>
    <visual name="right_forearm_link_visual">
      <origin rpy="0 1.57079632679 1.57079632679" xyz="0 0 0"/>
      <geometry name="right_forearm_link_geom">
        <mesh filename="package://bandit_urdf/meshes/bandit_mesh/forearm_cover_right_small.stl"/>
      </geometry>
      <material name="Arms"/>
    </visual>
    <collision name="right_forearm_link_collision">
      <origin rpy="0 0 0" xyz="0 0 -0.075"/>
      <geometry name="right_forearm_link_geom">
        <box size="0 0 0"/>
      </geometry>
    </collision>
  </link>
  <joint name="right_forearm_wrist_joint" type="revolute">
    <origin rpy="0 0 1.57079632679" xyz="0 0 -0.145"/>
    <axis xyz="0 0 -1"/>
    <parent link="right_forearm_link"/>
    <child link="right_wrist_link"/>
    <limit effort="30" lower="-1.57079632679" upper="1.57079632679" velocity="6"/>
    <dynamics damping="1.0"/>
    <calibration reference_position="0.0"/>
    <safety_controller k_position="100" k_velocity="10" soft_lower_limit="-1.57079632679" soft_upper_limit="1.57079632679"/>
  </joint>
  <link name="right_wrist_link">
    <inertial>
      <origin rpy="0 0 0" xyz="-0.026 0.163 -0.434"/>
      <mass value="0.01"/>
      <inertia ixx="0.866179142480" ixy="-0.06086507933" ixz="-0.12118061183" iyy="0.87421714893" iyz="-0.05886609911" izz="0.27353821674"/>
    </inertial>
    <visual name="right_wrist_link_visual">
      <origin rpy="1.57079632679 0 1.57079632679" xyz="0 0 -0.01"/>
      <geometry name="right_wrist_link_geom">
        <mesh filename="package://bandit_urdf/meshes/bandit_mesh/wrist_cover_right_small.stl"/>
      </geometry>
      <material name="Wrist"/>
    </visual>
    <collision name="">
      <origin rpy="0 0 0" xyz="0 0 -0.01"/>
      <geometry name="right_wrist_link_geom">
        <box size="0 0 0"/>
      </geometry>
    </collision>
  </link>
  <joint name="right_wrist_hand_joint" type="revolute">
    <origin xyz="0 0 -0.01"/>
    <axis xyz="0 -1 0"/>
    <parent link="right_wrist_link"/>
    <child link="right_hand_link"/>
    <limit effort="30" lower="-1.57079632679" upper="1.57079632679" velocity="6"/>
    <dynamics damping="1.0"/>
    <calibration reference_position="0.0"/>
    <safety_controller k_position="100" k_velocity="10" soft_lower_limit="-1.57079632679" soft_upper_limit="1.57079632679"/>
  </joint>
  <link name="right_hand_link">
    <inertial>
      <origin rpy="0.99408 0 1.5696" xyz="-0.015 0.163 -0.486"/>
      <mass value="0.01"/>
      <inertia ixx="0.866179142480" ixy="-0.06086507933" ixz="-0.12118061183" iyy="0.87421714893" iyz="-0.05886609911" izz="0.27353821674"/>
    </inertial>
    <visual name="right_hand_link_visual">
      <origin rpy="1.57079632679 0 0" xyz="0 0 -.00"/>
      <geometry name="right_hand_link_geom">
        <mesh filename="package://bandit_urdf/meshes/bandit_mesh/right_hand_small.stl"/>
      </geometry>
      <material name="Hands"/>
    </visual>
    <collision name="right_hand_link_collision">
      <origin rpy="0 0 0" xyz="-0.05 0 -0.06"/>
      <geometry name="right_hand_link_geom">
        <box size="0.03 0.06 0.080"/>
      </geometry>
    </collision>
  </link>
  <joint name="right_hand_thumb_joint" type="revolute">
    <origin xyz="0.014 0 -.033"/>
    <axis xyz="0 1 0"/>
    <parent link="right_hand_link"/>
    <child link="right_thumb_link"/>
    <limit effort="30" lower="-2.2853981634" upper="0" velocity="6"/>
    <dynamics damping="1.0"/>
    <calibration reference_position="0.0"/>
    <safety_controller k_position="100" k_velocity="10" soft_lower_limit="-2.1353981634" soft_upper_limit="-0.15"/>
  </joint>
  <link name="right_thumb_link">
    <inertial>
      <origin rpy="1.5696 0 1.5696" xyz="0.037 0.163 -0.484"/>
      <mass value="0.01"/>
      <inertia ixx="0.866179142480" ixy="-0.06086507933" ixz="-0.12118061183" iyy="0.87421714893" iyz="-0.05886609911" izz="0.27353821674"/>
    </inertial>
    <visual name="right_thumb_link_visual">
      <origin rpy="1.57079632679 -1.57079632679 0" xyz="0 0 0"/>
      <geometry name="right_thumb_link_geom">
        <mesh filename="package://bandit_urdf/meshes/bandit_mesh/right_thumb_small.stl"/>
      </geometry>
      <material name="Hands"/>
    </visual>
    <collision name="right_thumb_link_collision">
      <origin rpy="0 0 0" xyz="0 0 -.015"/>
      <geometry name="right_thumb_link_geom">
        <box size="0.030 0.025 0.06"/>
      </geometry>
    </collision>
  </link>
</robot>

